Workbook
Name Rango1: '[1]Instrucciones Formato'!$CG$495:$CH$505
Name Rango2: '[1]Instrucciones Formato'!$CJ$495:$CL$517
Name Rango3: '[1]Instrucciones Formato'!$CJ$495:$CL$517
Name Rodrigo: '[1]Instrucciones Formato'!#REF!

Sheet Matriz de Riesgos Cofrio
B1: MATRIZ DE IDENTIFICACION DE PELIGROS COMPAÑÍA OPOITA DE FRIOS SAS
B3: PROCESO | C3: Actividad | D3: Peligro | E3: Tipo de peligro | F3: Fuente | G3: Consecuencia | H3: ND (Nivel Deficiencia) | I3: NE (Nivel Exposicion) | J3: NP (Nivel de Probabilidad) | K3: INP (Interpretacion) | L3: NC (Nivel de Consecuencia) | M3: NR (Nivel del Riesgo) | N3: NTERPRETACIÓN DEL NIVEL DE RIESGO (NR) | O3: Aceptabilidad | P3: Controles | Q3: Controles a implementar | R3: Responsable | S3: fecha
B4: Producción de hielo y agua | C4: Manejo de cloro | D4: Sustancias químicas | E4: Químico | F4: Cloro | G4: Intoxicacion, Quemaduras | H4: 6 | I4: 3 | J4: =H4*I4 -> 18 | K4: =VLOOKUP(J4, Config!$B$4:$D$7, 3, 1) -> Alto | L4: 60 | M4: =J4*L4 -> 1080 | N4: =VLOOKUP(M4, Config!$F$4:$I$7, 3, 1) -> I. Situación crítica. Suspender actividades hasta que el riesgo esté bajo control. Intervención urgente. | O4: =VLOOKUP(M4, Config!$F$4:$I$7, 4, 1) -> No Aceptable | Q4: Sustitución, EPP, capacitación | R4: SST | S4: 2026
B5: Producción de hielo y agua | C5: Operación de bombas | D5: Partes móviles | E5: Mecánico | H5: 2 | I5: 3 | J5: =H5*I5 -> 6 | K5: =VLOOKUP(J5, Config!$B$4:$D$7, 3, 1) -> Bajo | L5: 25 | M5: =J5*L5 -> 150 | N5: =VLOOKUP(M5, Config!$F$4:$I$7, 3, 1) -> II .Corregir y adoptar medidas de control inmediato. Sin embargo, suspenda actividades si el nivel de consecuencia está por encima de 60. | O5: =VLOOKUP(M5, Config!$F$4:$I$7, 4, 1) -> No Aceptable | Q5: Guardas, mantenimiento | R5: SST | S5: 2026
B6: Producción de hielo y agua | C6: Áreas húmedas | D6: Piso resbaloso | E6: Locativo | H6: 2 | I6: 3 | J6: =H6*I6 -> 6 | K6: =VLOOKUP(J6, Config!$B$4:$D$7, 3, 1) -> Bajo | L6: 25 | M6: =J6*L6 -> 150 | N6: =VLOOKUP(M6, Config!$F$4:$I$7, 3, 1) -> II .Corregir y adoptar medidas de control inmediato. Sin embargo, suspenda actividades si el nivel de consecuencia está por encima de 60. | O6: =VLOOKUP(M6, Config!$F$4:$I$7, 4, 1) -> No Aceptable | Q6: Señalización | R6: SST | S6: 2026
B7: Producción de hielo y agua | C7: Operación de compresores | D7: Fuga de amoníaco | E7: Químico | H7: 10 | I7: 3 | J7: =H7*I7 -> 30 | K7: =VLOOKUP(J7, Config!$B$4:$D$7, 3, 1) -> Muy Alto | L7: 100 | M7: =J7*L7 -> 3000 | N7: =VLOOKUP(M7, Config!$F$4:$I$7, 3, 1) -> I. Situación crítica. Suspender actividades hasta que el riesgo esté bajo control. Intervención urgente. | O7: =VLOOKUP(M7, Config!$F$4:$I$7, 4, 1) -> No Aceptable | Q7: Detectores NH₃, ventilación | R7: SST | S7: 2026
B8: Producción de hielo y agua | C8: Mantenimiento | D8: Contacto NH₃ | E8: Químico | H8: 10 | I8: 2 | J8: =H8*I8 -> 20 | K8: =VLOOKUP(J8, Config!$B$4:$D$7, 3, 1) -> Alto | L8: 100 | M8: =J8*L8 -> 2000 | N8: =VLOOKUP(M8, Config!$F$4:$I$7, 3, 1) -> I. Situación crítica. Suspender actividades hasta que el riesgo esté bajo control. Intervención urgente. | O8: =VLOOKUP(M8, Config!$F$4:$I$7, 4, 1) -> No Aceptable | Q8: Permisos, SCBA | R8: SST | S8: 2026
B9: Producción de hielo y agua | C9: ingreso a cuartos frios | D9: Bajas temperaturas | E9: Físico | H9: 6 | I9: 3 | J9: =H9*I9 -> 18 | K9: =VLOOKUP(J9, Config!$B$4:$D$7, 3, 1) -> Alto | L9: 60 | M9: =J9*L9 -> 1080 | N9: =VLOOKUP(M9, Config!$F$4:$I$7, 3, 1) -> I. Situación crítica. Suspender actividades hasta que el riesgo esté bajo control. Intervención urgente. | O9: =VLOOKUP(M9, Config!$F$4:$I$7, 4, 1) -> No Aceptable | Q9: Ropa térmica | R9: SST | S9: 2026
B10: comercializacion | C10: Tránsito interno | D10: Atropellamiento | E10: Locativo | H10: 6 | I10: 2 | J10: =H10*I10 -> 12 | K10: =VLOOKUP(J10, Config!$B$4:$D$7, 3, 1) -> Alto | L10: 60 | M10: =J10*L10 -> 720 | N10: =VLOOKUP(M10, Config!$F$4:$I$7, 3, 1) -> I. Situación crítica. Suspender actividades hasta que el riesgo esté bajo control. Intervención urgente. | O10: =VLOOKUP(M10, Config!$F$4:$I$7, 4, 1) -> No Aceptable | Q10: Demarcación | R10: SST | S10: 2026
B11: comercializacion | C11: Conducción moto | D11: Accidente de tránsito | E11: Vial | H11: 10 | I11: 3 | J11: =H11*I11 -> 30 | K11: =VLOOKUP(J11, Config!$B$4:$D$7, 3, 1) -> Muy Alto | L11: 100 | M11: =J11*L11 -> 3000 | N11: =VLOOKUP(M11, Config!$F$4:$I$7, 3, 1) -> I. Situación crítica. Suspender actividades hasta que el riesgo esté bajo control. Intervención urgente. | O11: =VLOOKUP(M11, Config!$F$4:$I$7, 4, 1) -> No Aceptable | Q11: PESV, casco certificado | R11: SST | S11: 2026
B12: comercializacion | C12: Conducción vehículo | D12: Colisión | E12: Vial | H12: 6 | I12: 3 | J12: =H12*I12 -> 18 | K12: =VLOOKUP(J12, Config!$B$4:$D$7, 3, 1) -> Alto | L12: 100 | M12: =J12*L12 -> 1800 | N12: =VLOOKUP(M12, Config!$F$4:$I$7, 3, 1) -> I. Situación crítica. Suspender actividades hasta que el riesgo esté bajo control. Intervención urgente. | O12: =VLOOKUP(M12, Config!$F$4:$I$7, 4, 1) -> No Aceptable | Q12: Mantenimiento | R12: SST | S12: 2026
B13: comercializacion | C13: Fatiga | D13: Jornadas extensas | E13: Psicosocial | H13: 6 | I13: 2 | J13: =H13*I13 -> 12 | K13: =VLOOKUP(J13, Config!$B$4:$D$7, 3, 1) -> Alto | L13: 60 | M13: =J13*L13 -> 720 | N13: =VLOOKUP(M13, Config!$F$4:$I$7, 3, 1) -> I. Situación crítica. Suspender actividades hasta que el riesgo esté bajo control. Intervención urgente. | O13: =VLOOKUP(M13, Config!$F$4:$I$7, 4, 1) -> No Aceptable | Q13: Pausas | R13: SST | S13: 2026
B14: limpieza y desinfeccion | C14: Uso de químicos | D14: Vapores | E14: Químico | H14: 6 | I14: 3 | J14: =H14*I14 -> 18 | K14: =VLOOKUP(J14, Config!$B$4:$D$7, 3, 1) -> Alto | L14: 60 | M14: =J14*L14 -> 1080 | N14: =VLOOKUP(M14, Config!$F$4:$I$7, 3, 1) -> I. Situación crítica. Suspender actividades hasta que el riesgo esté bajo control. Intervención urgente. | O14: =VLOOKUP(M14, Config!$F$4:$I$7, 4, 1) -> No Aceptable | Q14: EPP, ventilación | R14: SST | S14: 2026
B15: mantenimiento | C15: Trabajo en altura | D15: Caídas | E15: Locativo | H15: 6 | I15: 2 | J15: =H15*I15 -> 12 | K15: =VLOOKUP(J15, Config!$B$4:$D$7, 3, 1) -> Alto | L15: 60 | M15: =J15*L15 -> 720 | N15: =VLOOKUP(M15, Config!$F$4:$I$7, 3, 1) -> I. Situación crítica. Suspender actividades hasta que el riesgo esté bajo control. Intervención urgente. | O15: =VLOOKUP(M15, Config!$F$4:$I$7, 4, 1) -> No Aceptable | Q15: Escaleras certificadas | R15: SST | S15: 2026

Sheet Config
B2: INTERPRETACIÓN NIVEL DEL PROBALIDAD | F2: INTERPTETACION NIVEL DE RIESGO Y ACEPTABILIDAD
B3: Rango Min | C3: Rango Max | D3: Interpretación (INP) | F3: Valor Min | G3: Nivel | H3: Interpretación del Riesgo | I3: Aceptabilidad
B4: 2 | C4: 4 | D4: Bajo | F4: 20 | G4: IV | H4: IV. Mantener las medidas de control existentes, pero se deberían considerar soluciones o mejoras y se deben hacer comprobaciones periódicas para asegurar que el riesgo aún es tolerable. | I4: Aceptable
B5: 8 | C5: 10 | D5: Medio | F5: 40 | G5: III | H5: III. Mejorar si es posible. Sería conveniente justificar la intervención y su rentabilidad. | I5: Aceptable
B6: 10 | C6: 20 | D6: Alto | F6: 150 | G6: II | H6: II .Corregir y adoptar medidas de control inmediato. Sin embargo, suspenda actividades si el nivel de consecuencia está por encima de 60. | I6: No Aceptable
B7: 24 | C7: 40 | D7: Muy Alto | F7: 600 | G7: I | H7: I. Situación crítica. Suspender actividades hasta que el riesgo esté bajo control. Intervención urgente. | I7: No Aceptable

Sheet Resumen Matriz
A1: MATRIZ DE IDENTIFICACIÓN DE PELIGROS
A2: COFRIO SAS
C4: Revisión inicial: 07/02/2022
C5: Actualización: Cada año o cuando existan cambios en el proceso.
A7: Nivel de Riesgo y de intervención NR = NP X NC | C7: Nivel de Probabilidad (NP)
C8: 40-24 | D8: 20-10 | E8: 8-6 | F8: 4-2
A9: Nivel de Consecuencias (NC) | B9: 100 | C9: I 4000 -2400 | D9: I 2000-1200 | E9: I 800-600 | F9: II 400-200
B10: 60 | C10: I 2400-1440 | D10: I 1200-600 | E10: II 480-360 | F10: II 240 - III 120
B11: 25 | C11: I 1000-600 | D11: II 500-250 | E11: II 200-150 | F11: III 100-50
B12: 10 | C12: II 400-240 | D12: II 200 - III 100 | E12: III 80-60 | F12: III 40 - VI 20
A14: De acuerdo a la resolución1072 DE 2015, la organización determina el riesgo y el nivel de riesgo para los peligros psicosociales a través de la aplicación de las baterías.

Sheet Instrucciones Formato
A1: INSTRUCCIONES PARA DILIGENCIAR EL FORMATO MATRIZ DE PELIGROS
A3: PROCESO: Especifique el proceso donde se están identificando las condiciones de trabajo. | N3: Nivel de Deficiencia | O3: ND | P3: Significado
N4: Muy Alto (MA) | O4: 10 | P4: Se han detectado peligros que determinan como muy posible la generación de incidentes, o la eficacia del conjunto de medidas preventivas existentes respecto al riesgo es nula o no existe o ambos.
A5: ACTIVIDAD: Marque con un X el tipo de actividad.
A6: ACTIVIDAD RUTINARIA: Actividad que forma parte de la operación normal de la organización, se ha planificado y es estandarizable. | N6: Alto (A) | O6: 6 | P6: Se han detectado algunos peligros que pueden dar lugar a consecuencias significativas, o la eficacia del conjunto de medidas preventivas existentes es baja, o ambos.
A7: ACTIVIDAD NO RUTINARIA: Actividad que no forma parte de la operación normal de la organización, que no estandarizable debido a la diversidad de escenarios y condiciones bajo las cuales pudiera presentarse.
N8: Medio (M) | O8: 2 | P8: Se han detectado peligros que pueden dar lugar a consecuencias poco significativas o de menor importancia, o la eficacia del conjunto de medidas preventivas existentes es moderada, o ambos.
A9: EXPUESTOS: Escriba el número de personas expuestas directa a un(os) peligro(s). Especifique si son de vinculados, temporales, de cooperativas o independientes.
N10: Bajo (B) | O10: No se asigna valor | P10: No se ha detectado anomalía destacable alguna, o la eficacia del conjunto de medidas preventivas existentes es alta, o ambos. El riesgo está controlado.
A11: PELIGRO: Fuente, situación o acto con potencial de daño en términos de enfermedad o lesión a las personas, o una combinación de estos (NTC OHSAS 18001).
A12: RIESGO: . Combinación de la probabilidad de que ocurra un(os) evento(s) o exposición(es) peligroso(s), y la severidad de lesión o enfermedad, que puede ser causado por el (los) evento(s) o la(s) exposición(es) (NTC-OHSAS 18001).
N13: Nivel de Exposición (NE) | O13: NE | P13: Significado
N14: Continua (EC) | O14: 4 | P14: La situación de exposición se presenta sin interrupción o varias veces con tiempo prolongado durante la jornada laboral.
A15: EFECTOS POSIBLES: Describa los efectos que reflejen las consecuencias de cada peligro identificado, es decir que se tengan en cuenta consecuencias a corto plazo como los de seguridad (accidente de trabajo), y las de largo plazo como las enfermedades. | N15: Frecuente (EF) | O15: 3 | P15: La situación de exposición se presenta varias veces durante la jornada laboral por tiempos cortos.
N16: Ocasional (EO) | O16: 2 | P16: La situación de exposición se presenta alguna vez durante la jornada laboral y por un periodo de tiempo corto.
N17: Esporádica (EE) | O17: 1 | P17: La situación de exposición se presenta de manera eventual.
A18: CONDICIONES DE HIGIENE: Son los peligros físicos, químicos, y biológicos que puedan generar enfermedades.
N19: Nivel de Probabilidad (NP) | O19: NP | P19: Significado
A20: CONDICIONES PSICOSOCIALES: Comprenden los aspectos intralaborales, los extralaborales o externos de la organización y las condiciones individuales o características intrínsecas del trabajador, los cuales en una interrelación dinámica, mediante percepciones y experiencias, influyen en la salud y el desempeño de las personas. Para el objeto de este instrumento no se incluirá la identificación de factor de riesgo sicosocial pues esta requiere el uso de otras herramientas especializadas. | N20: Muy Alto (MA) | O20: Entre 40 y 24 | P20: Situación deficiente con exposición continua, o muy deficiente con exposición frecuente. Normalmente la materialización del riesgo ocurre con frecuencia.
N22: Alto (A) | O22: Entre 20 y 10 | P22: Situación deficiente con exposición frecuente u ocasional, o bien situación muy deficiente con exposición ocasional o esporádica. La materialización del riesgo es posible que suceda varias veces en la vida laboral.
A24: CONDICIONES BIOMECÁNICAS: Son los peligros de carga dinámica o estática que pueden desencadenar incidentes y enfermedades. | N24: Medio (M) | O24: Entre 8 y 10 | P24: Situación deficiente con exposición esporádica, o bien situación mejorable con exposición continuada o frecuente. Es posible que suceda el daño alguna vez.
A26: CONDICIONES DE SEGURIDAD: Son los peligros mecánicos, eléctricos, locativos, tecnológicos y de tránsito que puedan desencadenar incidentes. | N26: Bajo (B) | O26: Entre 4 y 2 | P26: Situación mejorable con exposición ocasional o esporádica, o situación sin anomalía destacable con cualquier nivel de exposición. No es esperable que se materialice el riesgo, aunque puede ser concebible.
A28: RENDIMIENTOS NATURALES: Son los fenómenos naturales que afectan la seguridad y bienestar de las personas en el desarrollo de una actividad.
N29: Nivel de Consecuencias (NC) | O29: NC | P29: Significado Daños Personales
A30: CONDICIONES DE HIGIENE | B30: CONDICIONES PSICOSOCIALES | C30: CONDICIONES BIOMECÁNICAS | N30: Mortal o catastrófico (M) | O30: 100 | P30: Muerte (s).
N31: Muy Grave | O31: 60 | P31: Lesiones graves irreparables (incapacidad permanente parcial o invalidez).
A32: BIOLÓGICO | B32: Gestión organizacional (estilo de mando, pago, contratación, participación, inducción y capacitación, bienestar social, evaluación del desempeño, manejo de cambios) | C32: Postura (prolongada mantenida, forzada, antigravitaciones) | N32: Grave | O32: 25 | P32: Lesiones con incapacidad laboral temporal.
A33: Virus | N33: Leve | O33: 10 | P33: Lesiones que no requieren hospitalización.
A34: Bacterias | C34: Esfuerzo
A35: Hongos | C35: Movimiento repetitivo | N35: Nivel de Riesgo y de intervención NR = NP X NC | P35: Nivel de Probabilidad (NP)
A36: Ricketsias | C36: Manipulación manual de cargas | P36: 40-24 | Q36: 20-10 | R36: 8-6 | S36: 4-2
A37: Parásitos | C37: CONDICIONES DE SEGURIDAD | N37: Nivel de Consecuencias (NC) | O37: 100 | P37: I 4000 -2400 | Q37: I 2000-1200 | R37: I 800-600 | S37: II 400-200
A38: Picaduras | B38: Características de la organización del trabajo (comunicación, tecnología, organización del trabajo, demandas cualitativas y cuantitativas de la labor) | C38: Mecánico (elementos de máquinas, herramientas, piezas a trabajar, materiales proyectados sólidos o fluídos) | O38: 60 | P38: I 2400-1440 | Q38: I 1200-600 | R38: II 480-360 | S38: II - III
A39: Mordeduras | O39: 25 | P39: I 1000-600 | Q39: II 500-250 | R39: II 200-150 | S39: III 100-50
A40: Fluidos o excrementos | O40: 10 | P40: II 400-240 | Q40: II - III | R40: III 80-60 | S40: III - IV
A41: FÍSICO
A42: Ruido (impacto, intermitente y continuo) | C42: Eléctrico (alta y baja tensión, estática) | N42: Nivel de Riesgo y de intervención | O42: NR | P42: Significado
A44: Iluminación (luz visible por exceso o deficiencia) | B44: Características del grupo social del trabajo (relaciones, cohesión, calidad de interacciones, trabajo en equipo) | C44: Locativo (trabajo en alturas, trabajo en espacios confinados, almacenamiento, superficies de trabajo (irregularidades, deslizantes, con diferencia de nivel, condiciones de orden y aseo, caída de objetos) | N44: I | O44: 4000-600 | P44: Situación crítica. Suspender actividades hasta que el riesgo esté bajo control. Intervención urgente.
N45: II | O45: 500-150 | P45: Corregir y adoptar medidas de control inmediato. Sin embargo, suspenda actividades si el nivel de consecuencia está por encima de 60.
A46: Vibración (cuerpo entero, segmentaria) | N46: III | O46: 120-40 | P46: Mejorar si es posible. Sería conveniente justificar la intervención y su rentabilidad.
...

Sheet Hoja4
B4: PROCESO | C4: ACTIVIDAD | D4: TAREA | E4: PELIGRO | F4: TIPO DE PELIGRO | G4: FUENTE | H4: CONSECUENCIA | I4: ND =I4*I2 | J4: NE | K4: NP | L4: NC | M4: NR | N4: NIVEL DE RIESGO | O4: ACEPTABILIDAD | P4: CONTROLES EXISTENTES | Q4: CONTROLES A IMPLEMENTAR | R4: RESPONSABLE | S4: FECHA | T4: PLAN DE INTERVENCION
B6: PRODUCCION DE AGUA | C6: TRATAMIENTO | D6: MANEJO DE CLORO | E6: SUSTANCIAS QUIMICAS | F6: QUIMICO | G6: CLORO | H6: INTOXICACION, QUEMADURAS | I6: 6 | J6: 3 | K6: 18 | L6: 60 | M6: 1080 | N6: MUY ALTO | O6: NO ACEPTABLE | P6: FDS | Q6: EPP, VENTILACION/CAPACITACION | R6: VENTILACION/CAPACITACION | S6: 2026

Sheet PASO 2
B2: Proceso | Actividad | Tarea | Peligro | Tipo de Peligro | Fuente | Consecuencia | ND | NE | NP | NC | NR | Nivel de Riesgo | Aceptabilidad | Controles Existentes | Controles a Implementar | Responsable | Fecha
B4: Producción de agua | Tratamiento | Manejo de cloro | Sustancias químicas | Químico | Cloro | Intoxicación, quemaduras | 6 | 3 | 18 | 60 | 1080 | Muy Alto | No Aceptable | FDS | EPP, ventilación, capacitación | SST | 2026
B5: Producción de agua | Operación | Bombas | Partes móviles | Mecánico | Equipos | Golpes, atrapamientos | 2 | 3 | 6 | 25 | 150 | Medio | Aceptable con control | Guardas | Mantenimiento | SST | 2026
B6: Producción de agua | Limpieza | Pisos húmedos | Superficies resbalosas | Locativo | Agua | Caídas | 2 | 3 | 6 | 25 | 150 | Medio | Aceptable con control | Drenajes | Señalización | SST | 2026
B7: Producción de hielo | Operación | Compresores | Fuga de amoníaco | Químico | NH3 | Asfixia, muerte | 10 | 3 | 30 | 100 | 3000 | Muy Alto | No Aceptable | Mantenimiento | Detectores, ventilación | SST | 2026
B8: Producción de hielo | Mantenimiento | Tuberías | Contacto NH3 | Químico | NH3 | Quemaduras químicas | 10 | 2 | 20 | 100 | 2000 | Muy Alto | No Aceptable | Procedimientos | SCBA, permisos | SST | 2026
B9: Producción de hielo | Operación | Cámaras frías | Bajas temperaturas | Físico | Frío | Hipotermia | 6 | 3 | 18 | 60 | 1080 | Muy Alto | No Aceptable | Ropa térmica | Pausas, rotación | SST | 2026
B10: Bodega | Estiba | Apilamiento | Caída de objetos | Mecánico | Carga | Golpes | 6 | 2 | 12 | 25 | 300 | Alto | No Aceptable | Estantería | Capacitación | SST | 2026
B11: Bodega | Tránsito | Movilización | Atropellamiento | Locativo | Vehículos | Trauma | 6 | 2 | 12 | 60 | 720 | Alto | No Aceptable | Demarcación | Señalización | SST | 2026
B12: Distribución | Conducción | Moto | Accidente vial | Vial | Tránsito | Muerte | 10 | 3 | 30 | 100 | 3000 | Muy Alto | No Aceptable | Licencia | PESV, casco | SST | 2026
B13: Distribución | Conducción | Vehículo | Colisión | Vial | Tránsito | Lesiones graves | 6 | 3 | 18 | 100 | 1800 | Muy Alto | No Aceptable | Mantenimiento | Pausas activas | SST | 2026
B14: Distribución | Jornada | Fatiga | Cansancio | Psicosocial | Turnos | Accidente | 6 | 2 | 12 | 60 | 720 | Alto | No Aceptable | Horarios | Control jornadas | SST | 2026
