Workbook

Sheet TUBULAR VERDE
A1: COMPAÑÍA OPITA DE FRIO SAS | E1: VERDE
A2: CONTROL DE TIEMPO DE PRODUCCION
A3: LINEA TUBULAR
B4: TIEMPO HORARICA | E4: CONTROL HOROMETRO | H4: PRODUCTOS | O4: OBSERVACIONES
A5: FECHA | B5: HORA INICIO | C5: HORA FIN | D5: TIEMP PRENDIDA | E5: HOROM INC | F5: HOROM FIN | G5: TIEMP PROD | H5: BOLSA 1,5 KG | I5: BOLSA 3 KG | J5: BOLSA 7 KG | K5: BOLSA 15 KG | L5: BTO 25 KG | M5: KILOS PROD | N5: PROD POR | O5: AYUDANTE | P5: OBSERVACION
H6: 1.5 | I6: 3 | J6: 7 | K6: 15 | L6: 25 | N6: HORA | V6: maquina
A7: 46082 | B7: 0.26180556 | C7: 0.74583333 | D7: =1+C7-B7 -> 1.4840278 | E7: 1674091 | F7: 1675172 | G7: =(F7-E7)/100 -> 10.81 | K7: 128 | M7: =+(($H$6*H7)+($I$6*I7)+($J$6*J7)+($K$6*K7)+($L$6*L7)) -> 1920 | N7: =M7/G7 -> 177.61332 | O7: Hernandez Luis | V7: fecha | W7: 46093
A8: 46082 | B8: 0.77638889 | C8: 0.2375 | D8: =1+C8-B8 -> 0.46111111 | E8: =F7 -> 1675172 | F8: 1676369 | G8: =(F8-E8)/100 -> 11.97 | I8: 142 | K8: 98 | L8: 3 | M8: =+(($H$6*H8)+($I$6*I8)+($J$6*J8)+($K$6*K8)+($L$6*L8)) -> 1971 | N8: =M8/G8 -> 164.66165 | O8: Yinso Novoa
A9: 46083 | B9: 0.25694444 | C9: 0.57083333 | D9: =1+C9-B9 -> 1.3138889 | E9: =F8 -> 1676369 | F9: 1677141 | G9: 8 | I9: 134 | J9: 63 | K9: 40 | M9: =+(($H$6*H9)+($I$6*I9)+($J$6*J9)+($K$6*K9)+($L$6*L9)) -> 1443 | N9: =M9/G9 -> 180.375 | O9: James Quintero
A10: 46083 | B10: 0.60277778 | C10: 0.73819444 | D10: =1+C10-B10 -> 1.1354167 | E10: =F9 -> 1677141 | F10: 1677529 | G10: =(F10-E10)/100 -> 3.88 | H10: 34 | I10: 108 | J10: 17 | K10: 9 | M10: =+(($H$6*H10)+($I$6*I10)+($J$6*J10)+($K$6*K10)+($L$6*L10)) -> 629 | N10: =M10/G10 -> 162.1134 | O10: Daniel Garcia
A11: 46083 | B11: 0.75902778 | C11: 0.91180556 | D11: =1+C11-B11 -> 1.1527778 | E11: =F10 -> 1677529 | F11: 1677928 | G11: =(F11-E11)/100 -> 3.99 | I11: 126 | J11: 19 | M11: =+(($H$6*H11)+($I$6*I11)+($J$6*J11)+($K$6*K11)+($L$6*L11)) -> 511 | N11: =M11/G11 -> 128.07018 | O11: quejada diego
A12: 46083 | B12: 0.92847222 | C12: 0.24652778 | D12: =1+C12-B12 -> 0.31805556 | E12: =F11 -> 1677928 | F12: 1678738 | G12: =(F12-E12)/100 -> 8.1 | I12: 139 | K12: 69 | M12: =+(($H$6*H12)+($I$6*I12)+($J$6*J12)+($K$6*K12)+(L6*L12)) -> 1452 | N12: =M12/G12 -> 179.25926 | O12: James Quintero
A13: 46084 | B13: 0.25694444 | C13: 0.58125 | D13: =1+C13-B13 -> 1.3243056 | E13: =F12 -> 1678738 | F13: 1679480 | G13: 7 | K13: 90 | M13: =+(($H$6*H13)+($I$6*I13)+($J$6*J13)+($K$6*K13)+(13*L13)) -> 1350 | N13: =M13/G13 -> 192.85714 | O13: Andres Tinoco
A14: 46084 | B14: 0.60763889 | C14: 0.76458333 | D14: =1+C14-B14 -> 1.1569444 | E14: =F13 -> 1679480 | F14: 1679907 | G14: =(F14-E14)/100 -> 4.27 | K14: 55 | M14: =+(($H$6*H14)+($I$6*I14)+($J$6*J14)+($K$6*K14)+($L$6*L14)) -> 825 | N14: =M14/G14 -> 193.20843 | O14: Hernandez Luis
A15: 46084 | B15: 0.79930556 | C15: 0.90763889 | D15: =1+C15-B15 -> 1.1083333 | E15: =F14 -> 1679907 | F15: 1680270 | G15: =(F15-E15)/100 -> 3.63 | K15: 12 | L15: 18 | M15: =+(($H$6*H15)+($I$6*I15)+($J$6*J15)+($K$6*K15)+($L$6*L15)) -> 630 | N15: =M15/G15 -> 173.55372 | O15: Hernandez Luis
A16: 46084 | B16: 0.92152778 | C16: 0.24375 | D16: =1+C16-B16 -> 0.32222222 | E16: =F15 -> 1680270 | F16: 1681060 | G16: =(F16-E16)/100 -> 7.9 | I16: 141 | K16: 43 | L16: 18 | M16: =+(($H$6*H16)+($I$6*I16)+($J$6*J16)+($K$6*K16)+($L$6*L16)) -> 1518 | N16: =M16/G16 -> 192.1519 | O16: Jhoan Sebastian
A17: 46085 | B17: 0.25833333 | C17: 0.57986111 | D17: =1+C17-B17 -> 1.3215278 | E17: =F16 -> 1681060 | F17: 1681858 | G17: =(F17-E17)/100 -> 7.98 | I17: 146 | K17: 63 | M17: =+(($H$6*H17)+($I$6*I17)+($J$6*J17)+($K$6*K17)+($L$6*L17)) -> 1383 | N17: =M17/G17 -> 173.30827 | O17: Andres Tinoco
A18: 46085 | B18: 0.59375 | C18: 0.74305556 | D18: =1+C18-B18 -> 1.1493056 | E18: =F17 -> 1681858 | F18: 1682245 | G18: =(F18-E18)/100 -> 3.87 | I18: 119 | K18: 20 | M18: =+(($H$6*H18)+($I$6*I18)+($J$6*J18)+($K$6*K18)+($L$6*L18)) -> 657 | N18: =M18/G18 -> 169.76744 | O18: Daniel Garcia
A19: 46085 | B19: 0.76041667 | C19: 0.90972222 | D19: =1+C19-B19 -> 1.1493056 | E19: =F18 -> 1682245 | F19: 1682675 | G19: =(F19-E19)/100 -> 4.3 | I19: 18 | J19: 32 | K19: 19 | M19: =+(($H$6*H19)+($I$6*I19)+($J$6*J19)+($K$6*K19)+($L$6*L19)) -> 563 | N19: =M19/G19 -> 130.93023 | O19: Daniel Garcia
A20: 46085 | B20: 0.95138889 | C20: 0.24583333 | D20: =1+C20-B20 -> 0.29444444 | E20: =F19 -> 1682675 | F20: 1683370 | G20: =(F20-E20)/100 -> 6.95 | J20: 99 | K20: 43 | M20: =+(($H$6*H20)+($I$6*I20)+($J$6*J20)+($K$6*K20)+(13*L20)) -> 1338 | N20: =M20/G20 -> 192.51799 | O20: Jhoan Sebastian
A21: 46086 | B21: 0.27083333 | C21: 0.57638889 | D21: =1+C21-B21 -> 1.3055556 | E21: =F20 -> 1683370 | F21: 1684158 | G21: =(F21-E21)/100 -> 7.88 | H21: 30 | J21: 94 | K21: 36 | M21: =+(($H$6*H21)+($I$6*I21)+($J$6*J21)+($K$6*K21)+($L$6*L21)) -> 1243 | N21: =M21/G21 -> 157.74112 | O21: Luis Torres | P21: bajones de energia
A22: 46086 | B22: 0.59027778 | C22: 0.74166667 | D22: =1+C22-B22 -> 1.1513889 | E22: =F21 -> 1684158 | F22: 1684572 | G22: =(F22-E22)/100 -> 4.14 | J22: 68 | K22: 12 | M22: =+(($H$6*H22)+($I$6*I22)+($J$6*J22)+($K$6*K22)+($L$6*L22)) -> 656 | N22: =M22/G22 -> 158.45411 | O22: Daniel Garcia
A23: 46086 | B23: 0.75833333 | C23: 0.91111111 | D23: =1+C23-B23 -> 1.1527778 | E23: =F22 -> 1684572 | F23: 1684959 | G23: =(F23-E23)/100 -> 3.87 | J23: 32 | K23: 8 | L23: 168 | M23: =+(($H$6*H23)+($I$6*I23)+($J$6*J23)+($K$6*K23)+($L$6*L23)) -> 4544 | N23: =M23/G23 -> 1174.1602 | O23: Daniel Garcia
A24: 46086 | B24: 0.92708333 | C24: 0.24583333 | D24: =1+C24-B24 -> 0.31875 | E24: =F23 -> 1684959 | F24: 1685750 | G24: =(F24-E24)/100 -> 7.91 | K24: 91 | M24: =+(($H$6*H24)+($I$6*I24)+($J$6*J24)+($K$6*K24)+($L$6*L24)) -> 1365 | N24: =M24/G24 -> 172.56637 | O24: Jhoan Sebastian
A25: 46087 | B25: 0.26388889 | C25: 0.57777778 | D25: =1+C25-B25 -> 1.3138889 | E25: =F24 -> 1685750 | F25: 1686541 | G25: =(F25-E25)/100 -> 7.91 | I25: 166 | K25: 53 | M25: =+(($H$6*H25)+($I$6*I25)+($J$6*J25)+($K$6*K25)+($L$6*L25)) -> 1293 | N25: =M25/G25 -> 163.46397 | O25: James Quintero
A26: 46087 | B26: 0.59305556 | C26: 0.74583333 | D26: =1+C26-B26 -> 1.1527778 | E26: =F25 -> 1686541 | F26: 1686935 | G26: =(F26-E26)/100 -> 3.94 | K26: 45 | M26: =+(($H$6*H26)+($I$6*I26)+($J$6*J26)+($K$6*K26)+($L$6*L26)) -> 675 | N26: =M26/G26 -> 171.3198 | O26: Humberto
A27: 46087 | B27: 0.77152778 | C27: 0.90763889 | D27: =1+C27-B27 -> 1.1361111 | E27: =F26 -> 1686935 | F27: 1687321 | G27: =(F27-E27)/100 -> 3.86 | I27: 54 | K27: 28 | M27: =+(($H$6*H27)+($I$6*I27)+($J$6*J27)+($K$6*K27)+($L$6*L27)) -> 582 | N27: =M27/G27 -> 150.7772 | O27: Humberto
A28: 46087 | B28: 0.92361111 | C28: 0.23888889 | D28: =1+C28-B28 -> 0.31527778 | E28: =F27 -> 1687321 | F28: 1688120 | G28: 4 | I28: 90 | K28: 71 | M28: =+(($H$6*H28)+($I$6*I28)+($J$6*J28)+($K$6*K28)+($L$6*L28)) -> 1335 | N28: =M28/G28 -> 333.75 | O28: Jhoan Sebastian
A29: 46087 | B29: 0.92361111 | C29: 0.23888889 | D29: =1+C29-B29 -> 0.31527778 | E29: =F28 -> 1688120 | F29: 1688120 | G29: 8 | I29: 90 | K29: 71 | M29: =+(($H$6*H29)+($I$6*I29)+($J$6*J29)+($K$6*K29)+($L$6*L29)) -> 1335 | N29: =M29/G29 -> 166.875 | O29: Jhoan Sebastian
A30: 46088 | B30: 0.27083333 | C30: 0.57361111 | D30: =1+C30-B30 -> 1.3027778 | E30: =F29 -> 1688120 | F30: 1688916 | G30: =(F30-E30)/100 -> 7.96 | H30: 25 | I30: 116 | J30: 53 | K30: 40 | M30: =+(($H$6*H30)+($I$6*I30)+($J$6*J30)+($K$6*K30)+(L30*13)) -> 1356.5 | N30: =M30/G30 -> 170.41457 | O30: James Quintero
A31: 46088 | B31: 0.59305556 | C31: 0.76458333 | D31: =1+C31-B31 -> 1.1715278 | E31: =F30 -> 1688916 | F31: 1689340 | G31: =(F31-E31)/100 -> 4.24 | I31: 116 | J31: 43 | K31: 1 | M31: =+(($H$6*H31)+($I$6*I31)+($J$6*J31)+($K$6*K31)+($L$6*L31)) -> 664 | N31: =M31/G31 -> 156.60377 | O31: david
A32: 46088 | B32: 0.77708333 | C32: 0.90694444 | D32: =1+C32-B32 -> 1.1298611 | E32: =F31 -> 1689340 | F32: 1689707 | G32: =(F32-E32)/100 -> 3.67 | K32: 38 | M32: =+(($H$6*H32)+($I$6*I32)+($J$6*J32)+($K$6*K32)+($L$6*L32)) -> 570 | N32: =M32/G32 -> 155.31335 | O32: yeison
A33: 46088 | B33: 0.92569444 | C33: 0.24166667 | D33: =1+C33-B33 -> 0.31597222 | E33: =F32 -> 1689707 | F33: 1690485 | G33: =(F33-E33)/100 -> 7.78 | H33: 33 | I33: 139 | J33: 67 | K33: 34 | M33: =+(($H$6*H33)+($I$6*I33)+($J$6*J33)+($K$6*K33)+($L$6*L33)) -> 1445.5 | N33: =M33/G33 -> 185.79692 | O33: Jhoan Sebastian
A34: 46089 | B34: 0.26041667 | C34: 0.66319444 | D34: =1+C34-B34 -> 1.4027778 | E34: =F33 -> 1690485 | F34: 1691510 | G34: =(F34-E34)/100 -> 10.25 | I34: 122 | K34: 87 | M34: =+(($H$6*H34)+($I$6*I34)+($J$6*J34)+($K$6*K34)+($L$6*L34)) -> 1671 | N34: =M34/G34 -> 163.02439 | O34: oscar andres | P34: a ñlas 16:20 se fue la luz
A35: 46089 | B35: 0.038888889 | C35: 0.24305556 | D35: =1+C35-B35 -> 1.2041667 | E35: =F34 -> 1691510 | F35: 1692079 | G35: =(F35-E35)/100 -> 5.69 | I35: 138 | K35: 30 | M35: =+(($H$6*H35)+($I$6*I35)+($J$6*J35)+($K$6*K35)+($L$6*L35)) -> 864 | N35: =M35/G35 -> 151.84534 | O35: Daniel Garcia | P35: se prende la tubular verde a las 00:30
A36: 46090 | B36: 0.25833333 | C36: 0.57291667 | D36: =1+C36-B36 -> 1.3145833 | E36: =F35 -> 1692079 | F36: 1692832 | G36: 8 | I36: 61 | K36: 74 | M36: =+(($H$6*H36)+($I$6*I36)+($J$6*J36)+($K$6*K36)+($L$6*L36)) -> 1293 | N36: =M36/G36 -> 161.625 | O36: quejada diego
A37: 46090 | B37: 0.60277778 | C37: 0.74166667 | D37: =1+C37-B37 -> 1.1388889 | E37: =F36 -> 1692832 | F37: 1693235 | G37: =(F37-E37)/100 -> 4.03 | K37: 40 | L37: 2 | M37: =+(($H$6*H37)+($I$6*I37)+($J$6*J37)+($K$6*K37)+($L$6*L37)) -> 650 | N37: =M37/G37 -> 161.29032 | O37: david
A38: 46090 | B38: 0.77361111 | C38: 0.90902778 | D38: =1+C38-B38 -> 1.1354167 | E38: =F37 -> 1693235 | F38: 1693588 | G38: =(F38-E38)/100 -> 3.53 | I38: 139 | K38: 13 | M38: =+(($H$6*H38)+($I$6*I38)+($J$6*J38)+($K$6*K38)+(13*L38)) -> 612 | N38: =M38/G38 -> 173.3711 | O38: Humberto
A39: 46090 | B39: 0.92708333 | C39: 0.24652778 | D39: =1+C39-B39 -> 0.31944444 | E39: =F38 -> 1693588 | F39: 1694384 | G39: =(F39-E39)/100 -> 7.96 | I39: 185 | J39: 58 | K39: 14 | M39: =+(($H$6*H39)+($I$6*I39)+($J$6*J39)+($K$6*K39)+($L$6*L39)) -> 1171 | N39: =M39/G39 -> 147.11055 | O39: quejada diego
A40: 46091 | B40: 0.27638889 | C40: 0.575 | D40: =1+C40-B40 -> 1.2986111 | E40: =F39 -> 1694384 | F40: 1695176 | G40: =(F40-E40)/100 -> 7.92 | H40: 40 | J40: 99 | K40: 48 | M40: =+(($H$6*H40)+($I$6*I40)+($J$6*J40)+($K$6*K40)+($L$6*L40)) -> 1473 | N40: =M40/G40 -> 185.98485 | O40: Luis Torres
...

Sheet TUBULAR AZUL
A1: COMPAÑÍA OPITA DE FRIO SAS | E1: AZUL
A2: CONTROL DE TIEMPO DE PRODUCCION | R2: REEMPAQUE
A3: LINEA TUBULAR
B4: TIEMPO HORARICA | E4: CONTROL HOROMETRO | H4: PRODUCTOS | P4: OBSERVACIONES | R4: PRODUCTOS
A5: FECHA | B5: HORA INIC | C5: HORA FIN | D5: TIEMP PRENDIDA | E5: HOROM INC | F5: HOROM FIN | G5: TIEMP PROD | H5: BOLSA 1,5 KG | I5: BOLSA 3 KG | J5: BOLSA 7 KG | K5: BOLSA 15 KG | L5: BTO 25 KG | M5: KILOS PROD | N5: KILOS ACUMULADO | O5: PROD POR | P5: AYUDANTE | Q5: OBSERVACION | R5: BOLSA 1,5 KG | S5: BOLSA 3 KG | T5: BOLSA 7 KG | U5: BOLSA 15 KG | V5: BTO 20 KG | W5: KILOS REEMP | X5: KILOS ACUMULADO | Y5: UTILIZO
H6: 1.5 | I6: 3 | J6: 7 | K6: 15 | L6: 25 | O6: HORA | R6: 1.5 | S6: 3 | T6: 7 | U6: 15 | V6: 25 | Y6: EN
A7: 46082 | B7: 0.26041667 | C7: 0.73680556 | D7: =1+C7-B7 -> 1.4763889 | E7: 149866 | F7: 150983 | G7: =(F7-E7)/100 -> 11.17 | K7: 77 | M7: =+(($H$6*H7)+($I$6*I7)+($J$6*J7)+($K$6*K7)+($L$6*L7)) -> 1155 | N7: =+M7 -> 1155 | O7: =+M7/G7 -> 103.40197 | P7: Hernandez Luis | W7: - | X7: -
A8: 46082 | B8: 0.77638889 | C8: 0.24236111 | D8: =1+C8-B8 -> 0.46597222 | E8: =F7 -> 150983 | F8: 152183 | G8: =(F8-E8)/100 -> 12 | I8: 58 | K8: 69 | L8: 6 | M8: =+(($H$6*H8)+($I$6*I8)+($J$6*J8)+($K$6*K8)+($L$6*L8)) -> 1359 | N8: =+M8 -> 1359 | O8: =+M8/G8 -> 113.25 | P8: Yinso Nova | W8: - | X8: -
A9: 46083 | B9: 0.26875 | C9: 0.56944444 | D9: =1+C9-B9 -> 1.3006944 | E9: =F8 -> 152183 | F9: 152928 | G9: =(F9-E9)/100 -> 7.45 | I9: 68 | J9: 25 | K9: 18 | M9: =+(($H$6*H9)+($I$6*I9)+($J$6*J9)+($K$6*K9)+($L$6*L9)) -> 649 | N9: =+M9 -> 649 | O9: =+M9/G9 -> 87.114094 | P9: James Quintero | W9: - | X9: -
A10: 46083 | B10: 0.60833333 | C10: 0.73541667 | D10: =1+C10-B10 -> 1.1270833 | E10: =F9 -> 152928 | F10: 153308 | G10: =(F10-E10)/100 -> 3.8 | H10: 9 | I10: 59 | J10: 9 | K10: 6 | M10: =+(($H$6*H10)+($I$6*I10)+($J$6*J10)+($K$6*K10)+($L$6*L10)) -> 343.5 | N10: =+M10 -> 343.5 | O10: =+M10/G10 -> 90.394737 | P10: david | W10: - | X10: -
A11: 46083 | B11: 0.75902778 | C11: 0.90138889 | D11: =1+C11-B11 -> 1.1423611 | E11: =F10 -> 153308 | F11: 153740 | G11: =(F11-E11)/100 -> 4.32 | I11: 100 | J11: 7 | K11: 2 | M11: =+(($H$6*H11)+($I$6*I11)+($J$6*J11)+($K$6*K11)+($L$6*L11)) -> 379 | N11: =+M11 -> 379 | O11: =+M11/G11 -> 87.731481 | P11: quejada diego
A12: 46083 | B12: 0.92430556 | C12: 0.24652778 | D12: =1+C12-B12 -> 0.32222222 | E12: =F11 -> 153740 | F12: 154546 | G12: =(F12-E12)/100 -> 8.06 | I12: 61 | K12: 38 | M12: =+(($H$6*H12)+($I$6*I12)+($J$6*J12)+($K$6*K12)+($L$6*L12)) -> 753 | N12: =+M12 -> 753 | O12: =+M12/G12 -> 93.424318 | P12: Jhoan Sebastian | W12: - | X12: -
A13: 46084 | B13: 0.26944444 | C13: 0.57083333 | D13: =1+C13-B13 -> 1.3013889 | E13: =F12 -> 154546 | F13: 155319 | G13: =(F13-E13)/100 -> 7.73 | H13: 51 | K13: 44 | M13: =+(($H$6*H13)+($I$6*I13)+($J$6*J13)+($K$6*K13)+(13*L13)) -> 736.5 | N13: =+M13 -> 736.5 | O13: =+M13/G13 -> 95.278137 | P13: Andres Tinoco | W13: - | X13: -
A14: 46084 | B14: 0.60625 | C14: 0.75902778 | D14: =1+C14-B14 -> 1.1527778 | E14: =F13 -> 155319 | F14: 155747 | G14: =(F14-E14)/100 -> 4.28 | K14: 28 | M14: =+(($H$6*H14)+($I$6*I14)+($J$6*J14)+($K$6*K14)+($L$6*L14)) -> 420 | N14: =+M14 -> 420 | O14: =+M14/G14 -> 98.130841 | P14: Hernandez Luis | W14: - | X14: -
A15: 46084 | B15: 0.77222222 | C15: 0.90833333 | D15: =1+C15-B15 -> 1.1361111 | E15: =F14 -> 155747 | F15: 156112 | G15: =(F15-E15)/100 -> 3.65 | K15: 9 | L15: 12 | M15: =+(($H$6*H15)+($I$6*I15)+($J$6*J15)+($K$6*K15)+($L$6*L15)) -> 435 | N15: =+M15 -> 435 | O15: =+M15/G15 -> 119.17808 | P15: Hernandez Luis | W15: - | X15: -
A16: 46084 | B16: 0.92152778 | C16: 0.24930556 | D16: =1+C16-B16 -> 0.32777778 | E16: =F15 -> 156112 | F16: 156916 | G16: =(F16-E16)/100 -> 8.04 | I16: 60 | K16: 21 | L16: 5 | M16: =+(($H$6*H16)+($I$6*I16)+($J$6*J16)+($K$6*K16)+($L$6*L16)) -> 620 | N16: =+M16 -> 620 | O16: =+M16/G16 -> 77.114428 | P16: Jhoan Sebastian
A17: 46085 | B17: 0.27291667 | C17: 0.56736111 | D17: =1+C17-B17 -> 1.2944444 | E17: =F16 -> 156916 | F17: 157723 | G17: =(F17-E17)/100 -> 8.07 | I17: 92 | K17: 30 | M17: =+(($H$6*H17)+($I$6*I17)+($J$6*J17)+($K$6*K17)+($L$6*L17)) -> 726 | N17: =+M17 -> 726 | O17: =+M17/G17 -> 89.962825 | P17: Andres Tinoco | W17: - | X17: -
A18: 46085 | B18: 0.59375 | C18: 0.73958333 | D18: =1+C18-B18 -> 1.1458333 | E18: =F17 -> 157723 | F18: 158140 | G18: =(F18-E18)/100 -> 4.17 | I18: 50 | K18: 11 | M18: =+(($H$6*H18)+($I$6*I18)+($J$6*J18)+($K$6*K18)+($L$6*L18)) -> 315 | N18: =+M18 -> 315 | O18: =+M18/G18 -> 75.539568 | P18: Daniel Garcia | W18: - | X18: -
A19: 46085 | B19: 0.76041667 | C19: 0.90972222 | D19: =1+C19-B19 -> 1.1493056 | E19: =F18 -> 158140 | F19: 158504 | G19: =(F19-E19)/100 -> 3.64 | I19: 10 | J19: 19 | K19: 8 | M19: =+(($H$6*H19)+($I$6*I19)+($J$6*J19)+($K$6*K19)+($L$6*L19)) -> 283 | N19: =+M19 -> 283 | O19: =+M19/G19 -> 77.747253 | P19: Daniel Garcia | W19: - | X19: -
A20: 46087 | B20: 0.67569444 | C20: 0.73194444 | D20: =1+C20-B20 -> 1.05625 | E20: =F19 -> 158504 | F20: 159012 | G20: =(F20-E20)/100 -> 5.08 | K20: 10 | M20: =+(($H$6*H20)+($I$6*I20)+($J$6*J20)+($K$6*K20)+($L$6*L20)) -> 150 | N20: =+M20 -> 150 | O20: =+M20/G20 -> 29.527559 | P20: Humberto V | W20: - | X20: -
A21: 46087 | B21: 0.78888889 | C21: 0.90902778 | D21: =1+C21-B21 -> 1.1201389 | E21: =F20 -> 159012 | F21: 159405 | G21: =(F21-E21)/100 -> 3.93 | I21: 18 | K21: 9 | M21: =+(($H$6*H21)+($I$6*I21)+($J$6*J21)+($K$6*K21)+($L$6*L21)) -> 189 | N21: =+M21 -> 189 | O21: =+M21/G21 -> 48.091603 | P21: Humberto V
A22: 46087 | B22: 0.93125 | C22: 0.23958333 | D22: =1+C22-B22 -> 0.30833333 | E22: =F21 -> 159405 | F22: 160208 | G22: =(F22-E22)/100 -> 8.03 | I22: 50 | K22: 30 | M22: =+(($H$6*H22)+($I$6*I22)+($J$6*J22)+($K$6*K22)+($L$6*L22)) -> 600 | N22: =+M22 -> 600 | O22: =+M22/G22 -> 74.719801 | P22: Jhoan Sebastian | W22: - | X22: -
A23: 46088 | B23: 0.27430556 | C23: 0.57986111 | D23: =1+C23-B23 -> 1.3055556 | E23: =F22 -> 160208 | F23: 161020 | G23: =(F23-E23)/100 -> 8.12 | H23: 46 | I23: 38 | J23: 27 | K23: 16 | M23: =+(($H$6*H23)+($I$6*I23)+($J$6*J23)+($K$6*K23)+(13*L23)) -> 612 | N23: =+M23 -> 612 | O23: =+M23/G23 -> 75.369458 | P23: James Quintero
A24: 46088 | B24: 0.60208333 | C24: 0.76388889 | D24: =1+C24-B24 -> 1.1618056 | E24: =F23 -> 161020 | F24: 161433 | G24: =(F24-E24)/100 -> 4.13 | I24: 59 | J24: 29 | M24: =+(($H$6*H24)+($I$6*I24)+($J$6*J24)+($K$6*K24)+($L$6*L24)) -> 380 | N24: =+M24 -> 380 | O24: =+M24/G24 -> 92.009685 | P24: david
A25: 46088 | B25: 0.78194444 | C25: 0.90694444 | D25: =1+C25-B25 -> 1.125 | E25: =F24 -> 161433 | F25: 161815 | G25: =(F25-E25)/100 -> 3.82 | K25: 24 | M25: =+(($H$6*H25)+($I$6*I25)+($J$6*J25)+($K$6*K25)+($L$6*L25)) -> 360 | N25: =+M25 -> 360 | O25: =+M25/G25 -> 94.240838 | P25: yeison | W25: - | X25: -
A26: 46088 | B26: 0.92916667 | C26: 0.23680556 | D26: =1+C26-B26 -> 0.30763889 | E26: =F25 -> 161815 | F26: 162600 | G26: =(F26-E26)/100 -> 7.85 | H26: 17 | I26: 61 | J26: 33 | K26: 14 | M26: =+(($H$6*H26)+($I$6*I26)+($J$6*J26)+($K$6*K26)+($L$6*L26)) -> 649.5 | N26: =+M26 -> 649.5 | O26: =+M26/G26 -> 82.738854 | P26: Jhoan Sebastian | W26: - | X26: -
A27: 46089 | B27: 0.26041667 | C27: 0.66319444 | D27: =1+C27-B27 -> 1.4027778 | E27: =F26 -> 162600 | F27: 163632 | G27: =(F27-E27)/100 -> 10.32 | I27: 77 | K27: 46 | M27: =+(($H$6*H27)+($I$6*I27)+($J$6*J27)+($K$6*K27)+($L$6*L27)) -> 921 | N27: =+M27 -> 921 | O27: =+M27/G27 -> 89.244186 | P27: oscar andres | Q27: se apaga la maquinaria a las 16:20 por bajon de luz | W27: - | X27: -
A28: 46089 | B28: 0.038888889 | C28: 0.24027778 | D28: =1+C28-B28 -> 1.2013889 | E28: =F27 -> 163632 | F28: 164202 | G28: =(F28-E28)/100 -> 5.7 | I28: 62 | K28: 15 | M28: =+(($H$6*H28)+($I$6*I28)+($J$6*J28)+($K$6*K28)+(13*L28)) -> 411 | N28: =+M28 -> 411 | O28: =+M28/G28 -> 72.105263 | P28: Daniel Garcia | Q28: se prende maquinaria a las 00:30 | W28: - | X28: -
A29: 46090 | B29: 0.25694444 | C29: 0.56944444 | D29: =1+C29-B29 -> 1.3125 | E29: =F28 -> 164202 | F29: 164920 | G29: =(F29-E29)/100 -> 7.18 | I29: 40 | K29: 48 | M29: =+(($H$6*H29)+($I$6*I29)+($J$6*J29)+($K$6*K29)+($L$6*L29)) -> 840 | N29: =+M29 -> 840 | O29: =+M29/G29 -> 116.99164 | P29: quejada diego | W29: - | X29: -
A30: 46090 | B30: 0.60486111 | C30: 0.73333333 | D30: =1+C30-B30 -> 1.1284722 | E30: =F29 -> 164920 | F30: 165302 | G30: =(F30-E30)/100 -> 3.82 | K30: 24 | L30: 2 | M30: =+(($H$6*H30)+($I$6*I30)+($J$6*J30)+($K$6*K30)+(13*L30)) -> 386 | N30: =+M30 -> 386 | O30: =+M30/G30 -> 101.04712 | P30: Daniel Garcia | W30: - | X30: -
A31: 46090 | B31: 0.77777778 | C31: 0.90347222 | D31: =1+C31-B31 -> 1.1256944 | E31: =F30 -> 165302 | F31: 165693 | G31: =(F31-E31)/100 -> 3.91 | I31: 68 | K31: 8 | M31: =+(($H$6*H31)+($I$6*I31)+($J$6*J31)+($K$6*K31)+($L$6*L31)) -> 324 | N31: =+M31 -> 324 | O31: =+M31/G31 -> 82.86445 | P31: Humberto V | W31: - | X31: -
A32: 46090 | B32: 0.92361111 | C32: 0.23402778 | D32: =1+C32-B32 -> 0.31041667 | E32: =F31 -> 165693 | F32: 166485 | G32: =(F32-E32)/100 -> 7.92 | I32: 115 | J32: 36 | K32: 12 | M32: =+(($H$6*H32)+($I$6*I32)+($J$6*J32)+($K$6*K32)+(13*L32)) -> 777 | N32: =+M32 -> 777 | O32: =+M32/G32 -> 98.106061 | P32: Jhoan Sebastian | W32: - | X32: -
A33: 46091 | B33: 0.25347222 | C33: 0.575 | D33: =1+C33-B33 -> 1.3215278 | E33: =F32 -> 166485 | F33: 167280 | G33: =(F33-E33)/100 -> 7.95 | H33: 20 | J33: 51 | K33: 30 | M33: =+(($H$6*H33)+($I$6*I33)+($J$6*J33)+($K$6*K33)+($L$6*L33)) -> 837 | N33: =+M33 -> 837 | O33: =+M33/G33 -> 105.28302 | P33: Luis Torres | W33: - | X33: -
A34: 46091 | B34: 0.59722222 | C34: 0.74305556 | D34: =1+C34-B34 -> 1.1458333 | E34: =F33 -> 167280 | F34: 167691 | G34: =(F34-E34)/100 -> 4.11 | K34: 28 | M34: =+(($H$6*H34)+($I$6*I34)+($J$6*J34)+($K$6*K34)+(13*L34)) -> 420 | N34: =+M34 -> 420 | O34: =+M34/G34 -> 102.18978 | P34: oscar andres | W34: - | X34: -
A35: 46091 | B35: 0.77569444 | C35: 0.90486111 | D35: =1+C35-B35 -> 1.1291667 | E35: =F34 -> 167691 | F35: 168085 | G35: =(F35-E35)/100 -> 3.94 | K35: 27 | M35: =+(($H$6*H35)+($I$6*I35)+($J$6*J35)+($K$6*K35)+($L$6*L35)) -> 405 | N35: =+M35 -> 405 | O35: =+M35/G35 -> 102.79188 | P35: Hernandez Luis | W35: =+(($H$6*R35)+($I$6*S35)+($J$6*T35)+($K$6*U35)+($L$6*V35)) -> 0 | X35: =+W35 -> 0
A36: 46091 | B36: 0.91875 | C36: 0.24861111 | D36: =1+C36-B36 -> 0.32986111 | E36: 168085 | F36: 168882 | G36: =(F36-E36)/100 -> 7.97 | I36: 71 | K36: 43 | M36: =+(($H$6*H36)+($I$6*I36)+($J$6*J36)+($K$6*K36)+($L$6*L36)) -> 858 | N36: =+M36 -> 858 | O36: =+M36/G36 -> 107.6537 | P36: quejada diego
A37: 46090 | B37: 0.27083333 | C37: 0.55763889 | D37: =1+C37-B37 -> 1.2868056 | E37: =F36 -> 168882 | F37: 169588 | G37: =(F37-E37)/100 -> 7.06 | J37: 30 | K37: 24 | M37: =+(($H$6*H37)+($I$6*I37)+($J$6*J37)+($K$6*K37)+(13*L37)) -> 570 | N37: =+M37 -> 570 | O37: =+M37/G37 -> 80.736544 | P37: Andres Tinoco
A38: 46092 | B38: 0.75763889 | C38: 0.90347222 | D38: =1+C38-B38 -> 1.1458333 | E38: 169915 | F38: 170302 | G38: =(F38-E38)/100 -> 3.87 | K38: 27 | M38: =+(($H$6*H38)+($I$6*I38)+($J$6*J38)+($K$6*K38)+($L$6*L38)) -> 405 | N38: =+M38 -> 405 | O38: =+M38/G38 -> 104.65116 | P38: Luis Torres | W38: =+(($H$6*R38)+($I$6*S38)+($J$6*T38)+($K$6*U38)+($L$6*V38)) -> 0 | X38: =+W38 -> 0
A39: 46092 | B39: 0.92152778 | C39: 0.23819444 | D39: =1+C39-B39 -> 0.31666667 | E39: =F38 -> 170302 | F39: 171091 | G39: =(F39-E39)/100 -> 7.89 | I39: 109 | K39: 34 | M39: =+(($H$6*H39)+($I$6*I39)+($J$6*J39)+($K$6*K39)+(13*L39)) -> 837 | N39: =+M39 -> 837 | O39: =+M39/G39 -> 106.08365 | P39: quejada diego
A40: 46093 | B40: 0.26805556 | C40: 0.58333333 | D40: =1+C40-B40 -> 1.3152778 | E40: =F39 -> 171091 | F40: 171609 | G40: =(F40-E40)/100 -> 5.18 | J40: 36 | K40: 15 | L40: 2 | M40: =+(($H$6*H40)+($I$6*I40)+($J$6*J40)+($K$6*K40)+(13*L40)) -> 503 | N40: =+M40 -> 503 | O40: =+M40/G40 -> 97.104247 | P40: yeison | W40: =+(($H$6*R40)+($I$6*S40)+($J$6*T40)+($K$6*U40)+($L$6*V40)) -> 0 | X40: =+W40 -> 0
...

Sheet MAQUINA DE BOTELLONES
A1: COMPAÑÍA OPITA DE FRIO SAS | D1: MAQUINA BOTELLONES
A2: CONTROL DE TIEMPO DE PRODUCCION
A3: LINEA DEL AGUA
B4: TIEMPO HORARICA | E4: CONTROL HOROMETRO | H4: PRODUCTOS | J4: PROMED | K4: OBSERVACIONES
A5: FECHA | B5: HORA INIC | C5: HORA FIN | D5: TIEMP PRENDIDA | E5: HOROM INC | F5: HOROM FIN | G5: TIEMP PROD | H5: BOTELLON | I5: ACUM BOTELL | J5: BOT X HORA | K5: AYUDANTE | L5: PET 300*24 | M5: PET 500 *12 | N5: PET 500*12 GAS | O5: PET 600 *12 | P5: PET 5 litros | Q5: PET 600*12 GAS | R5: pet 1litro*6
E6: 0 | J6: -
A7: 46082 | B7: 0.33333333 | C7: 0.52083333 | D7: =+C7-B7 -> 0.1875 | E7: 61714 | F7: 61892 | G7: =(F7-E7)/100 -> 1.78 | H7: 149 | I7: =+H7 -> 149 | J7: =+H7/G7 -> 83.707865 | K7: Yinso Novoa | P7: 56
A8: 46083 | B8: 0.39652778 | C8: 0.49305556 | D8: =+C8-B8 -> 0.096527778 | E8: =F7 -> 61892 | F8: 61989 | G8: =(F8-E8)/100 -> 0.97 | H8: 63 | I8: =+H8 -> 63 | J8: =+H8/G8 -> 64.948454 | K8: luis torres | L8: 7
A9: 46083 | B9: 0.67361111 | C9: 0.75 | D9: =+C9-B9 -> 0.076388889 | E9: =F8 -> 61989 | F9: 62065 | G9: 6 | H9: 58 | I9: =+H9 -> 58 | J9: =+H9/G9 -> 9.6666667 | K9: humberto
A10: 46083 | B10: 0.038888889 | C10: 0.053472222 | D10: =+C10-B10 -> 0.014583333 | E10: =F9 -> 62065 | F10: 62095 | G10: 3 | H10: 23 | I10: =+H10 -> 23 | J10: =+H10/G10 -> 7.6666667 | K10: Yinso Novoa | P10: 84
A11: 46084 | B11: 0.38541667 | C11: 0.67361111 | D11: =+C11-B11 -> 0.28819444 | E11: =F10 -> 62095 | F11: 62297 | G11: 2 | H11: 166 | I11: =+H11 -> 166 | J11: =+H11/G11 -> 83 | K11: Miguel Mendoza
A12: 46085 | B12: 0.3125 | C12: 0.72777778 | D12: =+C12-B12 -> 0.41527778 | E12: =F11 -> 62297 | F12: 62781 | G12: =(F12-E12)/100 -> 4.84 | H12: 159 | I12: =+H12 -> 159 | J12: =+H12/G12 -> 32.85124 | K12: luis torres
A13: 46085 | B13: 0.79444444 | C13: 0.81944444 | D13: =+C13-B13 -> 0.025 | E13: =F12 -> 62781 | F13: 62842 | G13: =(F13-E13)/100 -> 0.61 | H13: 53 | I13: =+H13 -> 53 | J13: =+H13/G13 -> 86.885246 | K13: Hernandez Luis | L13: 10
A14: 46086 | B14: 0.39930556 | C14: 0.54513889 | D14: =+C14-B14 -> 0.14583333 | E14: =F13 -> 62842 | F14: 63000 | G14: =(F14-E14)/100 -> 1.58 | H14: 128 | I14: =+H14 -> 128 | J14: =+H14/G14 -> 81.012658 | K14: luis torres
A15: 46086 | B15: 0.79791667 | C15: 0.86388889 | D15: =+C15-B15 -> 0.065972222 | E15: =F14 -> 63000 | F15: 63067 | G15: =(F15-E15)/100 -> 0.67 | H15: 59 | I15: =+H15 -> 59 | J15: =+H15/G15 -> 88.059701 | K15: Hernandez Luis | L15: 11
A16: 46087 | B16: 0.41805556 | C16: 0.57291667 | D16: =+C16-B16 -> 0.15486111 | E16: =F15 -> 63067 | F16: 63226 | G16: =(F16-E16)/100 -> 1.59 | H16: 120 | I16: =+H16 -> 120 | J16: =+H16/G16 -> 75.471698 | K16: luis torres
A17: 46087 | B17: 0.95 | C17: 0.96041667 | D17: =+C17-B17 -> 0.010416667 | E17: =F16 -> 63226 | F17: 63294 | G17: =(F17-E17)/100 -> 0.68 | H17: 13 | I17: =+H17 -> 13 | J17: =+H17/G17 -> 19.117647 | K17: Yinso Novoa | P17: 84
A18: 46088 | B18: 0.61458333 | C18: 0.65416667 | D18: =+C18-B18 -> 0.039583333 | E18: =F17 -> 63294 | F18: 63383 | G18: 5 | H18: 79 | I18: =+H18 -> 79 | J18: =+H18/G18 -> 15.8 | K18: luis torres | P18: 56
A19: 46089 | B19: 0.59375 | C19: 0.61944444 | D19: =+C19-B19 -> 0.025694444 | E19: =F18 -> 63383 | F19: 63544 | G19: 1 | H19: 30 | I19: =+H19 -> 30 | J19: =+H19/G19 -> 30 | K19: luis torres
A20: 46090 | B20: 0.37777778 | C20: 0.46180556 | D20: =+C20-B20 -> 0.084027778 | E20: =F19 -> 63544 | F20: 63668 | G20: 1 | H20: 72 | I20: =+H20 -> 72 | J20: =+H20/G20 -> 72 | K20: Miguel Mendoza
A21: 46090 | B21: 0.95138889 | C21: 0.99166667 | D21: =+C21-B21 -> 0.040277778 | E21: =F20 -> 63668 | F21: 63784 | G21: 4 | H21: 63 | I21: =+H21 -> 63 | J21: =+H21/G21 -> 15.75 | K21: Hernandez Luis | P21: 56
A22: 46091 | B22: 0.39930556 | C22: 0.58333333 | D22: =+C22-B22 -> 0.18402778 | E22: =F21 -> 63784 | F22: 63868 | G22: =(F22-E22)/100 -> 0.84 | H22: 84 | I22: =+H22 -> 84 | J22: =+H22/G22 -> 100 | K22: Miguel Mendoza
A23: 46091 | B23: 0.94027778 | C23: 0.96111111 | D23: =+C23-B23 -> 0.020833333 | E23: =F22 -> 63868 | F23: 63925 | G23: =(F23-E23)/100 -> 0.57 | H23: 40 | I23: =+H23 -> 40 | J23: =+H23/G23 -> 70.175439 | K23: Hernandez Luis | P23: 56
A24: 46092 | B24: 0.44791667 | C24: 0.55138889 | D24: =+C24-B24 -> 0.10347222 | E24: =F23 -> 63925 | F24: 64022 | G24: 8 | H24: 62 | I24: =+H24 -> 62 | J24: =+H24/G24 -> 7.75 | K24: luis torres
A25: 46092 | B25: 0.75 | C25: 0.84027778 | D25: =+C25-B25 -> 0.090277778 | E25: =F24 -> 64022 | F25: 64119 | G25: =(F25-E25)/100 -> 0.97 | H25: 94 | I25: =+H25 -> 94 | J25: =+H25/G25 -> 96.907216 | K25: humberto
A26: 46093 | B26: 0.40972222 | C26: 0.49305556 | D26: =+C26-B26 -> 0.083333333 | E26: =F25 -> 64119 | F26: 64215 | G26: =(F26-E26)/100 -> 0.96 | H26: 76 | I26: =+H26 -> 76 | J26: =+H26/G26 -> 79.166667 | K26: Yinso Novoa
A27: 46093 | B27: 0.61597222 | C27: 0.70763889 | D27: =+C27-B27 -> 0.091666667 | E27: =F26 -> 64215 | F27: 64288 | G27: =(F27-E27)/100 -> 0.73 | H27: 54 | I27: =+H27 -> 54 | J27: =+H27/G27 -> 73.972603 | K27: luis torres
A28: 46093 | B28: 0.8125 | C28: 0.84027778 | D28: =+C28-B28 -> 0.027777778 | E28: =F27 -> 64288 | F28: 64335 | G28: =(F28-E28)/100 -> 0.47 | H28: 39 | I28: =+H28 -> 39 | J28: =+H28/G28 -> 82.978723 | K28: james | AF28: 2
A29: 46094 | B29: 0.375 | C29: 0.57291667 | D29: =+C29-B29 -> 0.19791667 | E29: =F28 -> 64335 | F29: 64517 | G29: =(F29-E29)/100 -> 1.82 | H29: 143 | I29: =+H29 -> 143 | J29: =+H29/G29 -> 78.571429 | K29: Miguel Mendoza
A30: 46094 | B30: 0.8125 | C30: 0.84791667 | D30: =+C30-B30 -> 0.035416667 | E30: =F29 -> 64517 | F30: 64559 | G30: =(F30-E30)/100 -> 0.42 | H30: 34 | I30: =+H30 -> 34 | J30: =+H30/G30 -> 80.952381 | K30: luis torres | P30: 56
A31: 46095 | B31: 0.43055556 | C31: 0.65625 | D31: =+C31-B31 -> 0.22569444 | E31: =F30 -> 64559 | F31: 64702 | G31: =(F31-E31)/100 -> 1.43 | H31: 88 | I31: =+H31 -> 88 | J31: =+H31/G31 -> 61.538462 | K31: luis torres
A32: 46095 | B32: 0.84027778 | C32: 0.88611111 | D32: =+C32-B32 -> 0.045833333 | E32: =F31 -> 64702 | F32: 64753 | G32: =(F32-E32)/100 -> 0.51 | H32: 43 | I32: =+H32 -> 43 | J32: =+H32/G32 -> 84.313725 | K32: humberto | P32: 56
D33: =+C33-B33 -> 0 | E33: =F32 -> 64753 | G33: =(F33-E33)/100 -> -647.53 | I33: =+H33 -> 0 | J33: =+H33/G33 -> 0 | K33: Miguel Mendoza
D34: =+C34-B34 -> 0 | E34: =F33 -> 0 | G34: =(F34-E34)/100 -> 0 | I34: =+H34 -> 0 | J34: =+H34/G34 -> #DIV/0!
D35: =+C35-B35 -> 0 | E35: =F34 -> 0 | G35: =(F35-E35)/100 -> 0 | I35: =+H35 -> 0 | J35: =+H35/G35 -> #DIV/0! | K35: Miguel Mendoza
D36: =+C36-B36 -> 0 | E36: =F35 -> 0 | G36: 1 | I36: =+H36 -> 0 | J36: =+H36/G36 -> 0 | K36: humberto
D37: =+C37-B37 -> 0 | E37: =F36 -> 0 | G37: =(F37-E37)/100 -> 0 | I37: =+H37 -> 0 | J37: =+H37/G37 -> #DIV/0! | K37: Hernandez Luis
D38: =+C38-B38 -> 0 | E38: =F37 -> 0 | G38: =(F38-E38)/100 -> 0 | I38: =+H38 -> 0 | J38: =+H38/G38 -> #DIV/0! | K38: Miguel Mendoza
D39: =+C39-B39 -> 0 | E39: =F38 -> 0 | G39: =(F39-E39)/100 -> 0 | I39: =+H39 -> 0 | J39: =+H39/G39 -> #DIV/0! | K39: Yinso Novoa
D40: =+C40-B40 -> 0 | E40: =F39 -> 0 | G40: =(F40-E40)/100 -> 0 | I40: =+H40 -> 0 | J40: =+H40/G40 -> #DIV/0! | K40: Hernandez Luis
...

Sheet MAQUINA DE AGUA 350
A1: COMPAÑÍA OPITA DE FRIO SAS | F1: MAQUINA 350ML
A2: CONTROL DE TIEMPO DE PRODUCCION
A3: LINEA DEL AGUA
B4: TIEMPO HORARICA | E4: CONTROL UNIDADES | H4: PRODUCTOS | M4: PLASTICO | N4: CONVERS | O4: PROMEDIO | P4: DESPERDICIO | Q4: OBSERVACIONES
A5: FECHA | B5: HORA INIC | C5: HORA FIN | D5: TIEMP PRENDIDA | E5: UNIDAD BUENAS | F5: UNIDAD DAÑADAS | G5: TOTAL DE UNIDADES | H5: PACA X 15 UNID | I5: PACA X 24 UNID | J5: BOLSA DE 6 LITROS | K5: ACUM X 15 | L5: ACUM X 24 | M5: UTILIZ KILOS | N5: PACAS POR DE 15 UNID | O5: PROD X KILO | P5: EN KILOS | Q5: AYUDANTE | R5: OBSERVACION
A7: 46083 | B7: 0.36111111 | C7: 0.69791667 | D7: =C7-B7 -> 0.33680556 | E7: =H7*15+I7*24 -> 11052 | H7: 300 | I7: 273 | J7: 260 | K7: =H7*15 -> 4500 | L7: =I7*24 -> 6552 | N7: =(I7*24/15)+H7 -> 736.8 | O7: #DIV/0! | P7: =+F7*0.003 -> 0 | Q7: Miguel Mendoza
A8: 46085 | B8: 0.36805556 | C8: 0.65972222 | D8: =C8-B8 -> 0.29166667 | E8: 4575 | H8: 350 | I8: 207 | J8: 140 | K8: =H8*15 -> 5250 | L8: =I8*24 -> 4968 | N8: =(I8*24/15)+H8 -> 681.2 | O8: #DIV/0! | P8: =+F8*0.003 -> 0 | Q8: Miguel Mendoza
A9: 46085 | B9: 0.3125 | C9: 0.22777778 | D9: =C9-B9 -> -0.084722222 | E9: =(H9*15)+(I9*24) -> 0 | K9: =H9*15 -> 0 | L9: =I9*24 -> 0 | N9: =(I9*24/15)+H9 -> 0 | O9: #DIV/0! | P9: =+F9*0.003 -> 0 | Q9: Miguel Mendoza
A10: 46086 | B10: 0.59722222 | C10: 0.69791667 | D10: =C10-B10 -> 0.10069444 | E10: =(H10*15)+(I10*24) -> 3645 | H10: 35 | I10: 130 | J10: 120 | K10: =H10*15 -> 525 | L10: =I10*24 -> 3120 | N10: =(I10*24/15)+H10 -> 243 | O10: #DIV/0! | P10: =+F10*0.003 -> 0 | Q10: Miguel Mendoza
A11: 46087 | B11: 0.39583333 | C11: 0.6875 | D11: =C11-B11 -> 0.29166667 | E11: =(H11*15)+(I11*24) -> 5655 | H11: 233 | I11: 90 | K11: =H11*15 -> 3495 | L11: =I11*24 -> 2160 | N11: =(I11*24/15)+H11 -> 377 | O11: #DIV/0! | P11: =+F11*0.003 -> 0 | Q11: Miguel Mendoza
A12: 46088 | B12: 0.39583333 | C12: 0.65277778 | D12: =C12-B12 -> 0.25694444 | E12: =(H12*15)+(I12*24) -> 9252 | H12: 100 | I12: 323 | J12: 160 | K12: =H12*15 -> 1500 | L12: =I12*24 -> 7752 | N12: =(I12*24/15)+H12 -> 616.8 | O12: #DIV/0! | P12: =+F12*0.003 -> 0 | Q12: Miguel Mendoza
A13: 46090 | B13: 0.52777778 | C13: 0.70138889 | D13: =C13-B13 -> 0.17361111 | E13: =(H13*15)+(I13*24) -> 6870 | H13: 266 | I13: 120 | J13: 200 | K13: =H13*15 -> 3990 | L13: =I13*24 -> 2880 | N13: =(I13*24/15)+H13 -> 458 | O13: =+N13/M13 -> #DIV/0! | P13: =+F13*0.003 -> 0 | Q13: Miguel Mendoza
A14: 46091 | B14: 0.63194444 | C14: 0.74305556 | D14: =C14-B14 -> 0.11111111 | E14: =(H14*15)+(I14*24) -> 4080 | I14: 170 | J14: 140 | K14: =H14*15 -> 0 | L14: =I14*24 -> 4080 | N14: =(I14*24/15)+H14 -> 272 | O14: =+N14/M14 -> #DIV/0! | P14: =+F14*0.003 -> 0 | Q14: Miguel Mendoza
A15: 46092 | B15: 0.375 | C15: 0.54166667 | D15: =C15-B15 -> 0.16666667 | E15: =(H15*15)+(I15*24) -> 6750 | H15: 450 | K15: =H15*15 -> 6750 | L15: =I15*24 -> 0 | N15: =(I15*24/15)+H15 -> 450 | O15: =+N15/M15 -> #DIV/0! | P15: =+F15*0.003 -> 0 | Q15: Miguel Mendoza
D16: =C16-B16 -> 0 | E16: =(H16*15)+(I16*24) -> 0 | K16: =H16*15 -> 0 | L16: =I16*24 -> 0 | N16: =(I16*24/15)+H16 -> 0 | O16: =+N16/M16 -> #DIV/0! | P16: 0
D17: =C17-B17 -> 0 | E17: =(H17*15)+(I17*24) -> 0 | K17: =H17*15 -> 0 | L17: =I17*24 -> 0 | N17: =(I17*24/15)+H17 -> 0 | O17: =+N17/M17 -> #DIV/0! | P17: 0.246
D18: =C18-B18 -> 0 | E18: =(H18*15)+(I18*24) -> 0 | K18: =H18*15 -> 0 | L18: =I18*24 -> 0 | N18: =(I18*24/15)+H18 -> 0 | O18: =+N18/M18 -> #DIV/0! | P18: 0
D19: =C19-B19 -> 0 | E19: =(H19*15)+(I19*24) -> 0 | K19: =H19*15 -> 0 | L19: =I19*24 -> 0 | N19: =(I19*24/15)+H19 -> 0 | O19: =+N19/M19 -> #DIV/0! | P19: =+F19*0.003 -> 0
A20: 46093 | B20: 0.38194444 | C20: 0.68402778 | D20: =C20-B20 -> 0.30208333 | E20: =(H20*15)+(I20*24) -> 6234 | H20: 150 | I20: 166 | K20: =H20*15 -> 2250 | L20: =I20*24 -> 3984 | N20: =(I20*24/15)+H20 -> 415.6 | O20: =+N20/M20 -> #DIV/0! | P20: =+F20*0.003 -> 0 | Q20: Miguel Mendoza
A21: 46094 | B21: 0.52083333 | C21: 0.59722222 | D21: =C21-B21 -> 0.076388889 | E21: =(H21*15)+(I21*24) -> 2880 | I21: 120 | J21: 100 | K21: =H21*15 -> 0 | L21: =I21*24 -> 2880 | N21: =(I21*24/15)+H21 -> 192 | O21: =+N21/M21 -> #DIV/0! | P21: =+F21*0.003 -> 0 | Q21: Miguel Mendoza
A22: 46095 | B22: 0.36111111 | C22: 0.52083333 | D22: =C22-B22 -> 0.15972222 | E22: =(H22*15)+(I22*24) -> 5325 | H22: 187 | I22: 105 | K22: =H22*15 -> 2805 | L22: =I22*24 -> 2520 | N22: =(I22*24/15)+H22 -> 355 | O22: =+N22/M22 -> #DIV/0! | P22: =+F22*0.003 -> 0 | Q22: Miguel Mendoza
D23: =C23-B23 -> 0 | E23: =(H23*15)+(I23*24) -> 0 | K23: =H23*15 -> 0 | L23: =I23*24 -> 0 | N23: =(I23*24/15)+H23 -> 0 | O23: =+N23/M23 -> #DIV/0! | P23: =+F23*0.003 -> 0 | Q23: Miguel Mendoza
D24: =+C24-B24 -> 0 | E24: =(H24*15)+(I24*24) -> 0 | K24: =H24*15 -> 0 | L24: =I24*24 -> 0 | N24: =(I24*24/15)+H24 -> 0 | O24: =+N24/M24 -> #DIV/0! | P24: =+F24*0.003 -> 0 | Q24: Miguel Mendoza
D25: =+C25-B25 -> 0 | E25: =(H25*15)+(I25*24) -> 0 | K25: =H25*15 -> 0 | L25: =I25*24 -> 0 | N25: =(I25*24/15)+H25 -> 0 | O25: =+N25/M25 -> #DIV/0! | P25: =+F25*0.003 -> 0 | Q25: Miguel Mendoza
D26: =+C26-B26 -> 0 | E26: =(H26*15)+(I26*24) -> 0 | K26: =H26*15 -> 0 | L26: =I26*24 -> 0 | N26: =(I26*24/15)+H26 -> 0 | O26: =+N26/M26 -> #DIV/0! | P26: =+F26*0.003 -> 0
D27: =+C27-B27 -> 0 | E27: =(H27*15)+(I27*24) -> 0 | K27: =H27*15 -> 0 | L27: =I27*24 -> 0 | N27: =(I27*24/15)+H27 -> 0 | O27: =+N27/M27 -> #DIV/0! | P27: =+F27*0.003 -> 0
D28: =+C28-B28 -> 0 | E28: =(H28*15)+(I28*24) -> 0 | K28: =H28*15 -> 0 | L28: =I28*24 -> 0 | N28: =(I28*24/15)+H28 -> 0 | O28: =+N28/M28 -> #DIV/0! | P28: =+F28*0.003 -> 0 | Q28: Miguel Mendoza
D29: =+C29-B29 -> 0 | E29: =(H29*15)+(I29*24) -> 0 | K29: =H29*15 -> 0 | L29: =I29*24 -> 0 | N29: =(I29*24/15)+H29 -> 0 | O29: =+N29/M29 -> #DIV/0! | P29: =+F29*0.003 -> 0 | Q29: Miguel Mendoza
D30: =+C30-B30 -> 0 | E30: =(H30*15)+(I30*24) -> 0 | K30: =H30*15 -> 0 | L30: =I30*24 -> 0 | N30: =(I30*24/15)+H30 -> 0 | O30: =+N30/M30 -> #DIV/0!
D31: =+C31-B31 -> 0 | E31: =(H31*15)+(I31*24) -> 0 | K31: =H31*15 -> 0 | L31: =I31*24 -> 0 | N31: =(I31*24/15)+H31 -> 0 | O31: =+N31/M31 -> #DIV/0! | P31: =+F31*0.003 -> 0 | Q31: Miguel Mendoza
D32: =+C32-B32 -> 0 | E32: =(H32*15)+(I32*24) -> 0 | K32: =H32*15 -> 0 | L32: =I32*24 -> 0 | N32: =(I32*24/15)+H32 -> 0 | O32: =+N32/M32 -> #DIV/0! | P32: =+F32*0.003 -> 0 | Q32: Miguel Mendoza
D33: =+C33-B33 -> 0 | E33: =(H33*15)+(I33*24) -> 0 | K33: =H33*15 -> 0 | L33: =I33*24 -> 0 | N33: =(I33*24/15)+H33 -> 0 | O33: =+N33/M33 -> #DIV/0! | P33: =+F33*0.003 -> 0 | Q33: Miguel Mendoza
D34: =+C34-B34 -> 0 | E34: =(H34*15)+(I34*24) -> 0 | K34: =H34*15 -> 0 | L34: =I34*24 -> 0 | N34: =(I34*24/15)+H34 -> 0 | O34: =+N34/M34 -> #DIV/0! | P34: =+F34*0.003 -> 0 | Q34: Miguel Mendoza
D35: =+C35-B35 -> 0 | E35: =(H35*15)+(I35*24) -> 0 | K35: =H35*15 -> 0 | L35: =I35*24 -> 0 | N35: =(I35*24/15)+H35 -> 0 | O35: =+N35/M35 -> #DIV/0! | P35: =+F35*0.003 -> 0
D36: =+C36-B36 -> 0 | E36: =(H36*15)+(I36*24) -> 0 | K36: =H36*15 -> 0 | L36: =I36*24 -> 0 | N36: =(I36*24/15)+H36 -> 0 | O36: =+N36/M36 -> #DIV/0! | P36: =+F36*0.003 -> 0
D37: =+C37-B37 -> 0 | E37: =(H37*15)+(I37*24) -> 0 | K37: =H37*15 -> 0 | L37: =I37*24 -> 0 | N37: =(I37*24/15)+H37 -> 0 | O37: =+N37/M37 -> #DIV/0! | P37: =+F37*0.003 -> 0
D38: =+C38-B38 -> 0 | E38: =(H38*15)+(I38*24) -> 0 | K38: =H38*15 -> 0 | L38: =I38*24 -> 0 | N38: =(I38*24/15)+H38 -> 0 | O38: =+N38/M38 -> #DIV/0! | P38: =+F38*0.003 -> 0
D39: =+C39-B39 -> 0 | E39: =(H39*15)+(I39*24) -> 0 | K39: =H39*15 -> 0 | L39: =I39*24 -> 0 | N39: =(I39*24/15)+H39 -> 0 | O39: =+N39/M39 -> #DIV/0! | P39: =+F39*0.003 -> 0
D40: =+C40-B40 -> 0 | E40: =(H40*15)+(I40*24) -> 0 | K40: =H40*15 -> 0 | L40: =I40*24 -> 0 | N40: =(I40*24/15)+H40 -> 0 | O40: =+N40/M40 -> #DIV/0! | P40: =+F40*0.003 -> 0
D41: =+C41-B41 -> 0 | E41: =(H41*15)+(I41*24) -> 0 | K41: =H41*15 -> 0 | L41: =I41*24 -> 0 | N41: =(I41*24/15)+H41 -> 0 | O41: =+N41/M41 -> #DIV/0! | P41: =+F41*0.003 -> 0
...

Sheet GRIS
A1: COMPAÑÍA OPITA DE FRIO SAS | E1: GRIS
A2: CONTROL DE TIEMPO DE PRODUCCION
A3: LINEA TUBULAR
B4: TIEMPO HORARICA | E4: CONTROL HOROMETRO | H4: PRODUCTOS | P4: OBSERVACIONES
A5: FECHA | B5: HORA INICIO | C5: HORA FIN | D5: TIEMP PRENDIDA | E5: HOROM INC | F5: HOROM FIN | G5: TIEMP PROD | H5: 1,5KG | I5: BOLSA 3KG | J5: ARROBA FINA | K5: BOLSA 7 KG | L5: BOLSA 15 KG | M5: BTO 25 KG | N5: KILOS PROD | O5: PROD POR | P5: AYUDANTE | Q5: OBSERVACION
H6: 1.5 | I6: 3 | J6: 14 | K6: 7 | L6: 15 | M6: 25 | O6: HORA
A7: 46082 | B7: 0.28472222 | C7: 0.73611111 | D7: =1+C7-B7 -> 1.4513889 | E7: 2336532 | F7: 2337679 | G7: =(F7-E7)/100 -> 11.47 | M7: 174 | N7: =+(($H$6*H7)+($J$6*J7)+($K$6*K7)+($L$6*L7)+($M$6*M7)+(I7*3)) -> 4350 | O7: =N7/G7 -> 379.25022 | P7: Daniel Garcia | Q7: se apaga maquinaria 30 min por najo
A8: 46082 | B8: 0.75694444 | C8: 0.24444444 | D8: =1+C8-B8 -> 0.4875 | E8: =F7 -> 2337679 | F8: 2338900 | G8: =(F8-E8)/100 -> 12.21 | M8: 192 | N8: =+(($H$6*H8)+($J$6*J8)+($K$6*K8)+($L$6*L8)+($M$6*M8)+(I8*3)) -> 4800 | O8: =N8/G8 -> 393.12039 | P8: Michell Romero
A9: 46083 | B9: 0.26111111 | C9: 0.56944444 | D9: =1+C9-B9 -> 1.3083333 | E9: =F8 -> 2338900 | F9: 2339712 | G9: =(F9-E9)/100 -> 8.12 | M9: 115 | N9: =+(($H$6*H9)+($J$6*J9)+($K$6*K9)+($L$6*L9)+($M$6*M9)+(I9*3)) -> 2875 | O9: =N9/G9 -> 354.06404 | P9: yeison
A10: 46083 | B10: 0.58680556 | C10: 0.73402778 | D10: =1+C10-B10 -> 1.1472222 | E10: =F9 -> 2339712 | F10: 2340065 | G10: =(F10-E10)/100 -> 3.53 | M10: 24 | N10: =+(($H$6*H10)+($J$6*J10)+($K$6*K10)+($L$6*L10)+($M$6*M10)+(I10*3)) -> 600 | O10: =N10/G10 -> 169.97167 | P10: quejada diego
A11: 46083 | B11: 0.76388889 | C11: 0.90347222 | D11: =1+C11-B11 -> 1.1395833 | E11: =F10 -> 2340065 | F11: 2340432 | G11: =(F11-E11)/100 -> 3.67 | M11: 64 | N11: =+(($H$6*H11)+($J$6*J11)+($K$6*K11)+($L$6*L11)+($M$6*M11)+(I11*3)) -> 1600 | O11: =N11/G11 -> 435.9673 | P11: david | R11: f
A12: 46083 | B12: 0.91875 | C12: 0.23263889 | D12: =1+C12-B12 -> 0.31388889 | E12: =F11 -> 2340432 | F12: 2341285 | G12: 8 | M12: 126 | N12: =+(($H$6*H12)+($J$6*J12)+($K$6*K12)+($L$6*L12)+($M$6*M12)+(I12*3)) -> 3150 | O12: =N12/G12 -> 393.75 | P12: Michell Romero
A13: 46084 | B13: 0.25833333 | C13: 0.57777778 | D13: =1+C13-B13 -> 1.3194444 | E13: =F12 -> 2341285 | F13: 2342017 | G13: =(F13-E13)/100 -> 7.32 | J13: 53 | M13: 84 | N13: =+(($H$6*H13)+($J$6*J13)+($K$6*K13)+($L$6*L13)+($M$6*M13)+(I13*3)) -> 2842 | O13: =N13/G13 -> 388.25137 | P13: luis torres
A14: 46084 | B14: 0.59375 | C14: 0.7375 | D14: =1+C14-B14 -> 1.14375 | E14: =F13 -> 2342017 | F14: 2342401 | G14: 8 | M14: 54 | N14: =+(($H$6*H14)+($J$6*J14)+($K$6*K14)+($L$6*L14)+($M$6*M14)+(I14*3)) -> 1350 | O14: =N14/G14 -> 168.75 | P14: quejada diego
A15: 46084 | B15: 0.76111111 | C15: 0.90277778 | D15: =1+C15-B15 -> 1.1416667 | E15: =F14 -> 2342401 | F15: 2342794 | G15: 8 | M15: 58 | N15: =+(($H$6*H15)+($J$6*J15)+($K$6*K15)+($L$6*L15)+($M$6*M15)+(I15*3)) -> 1450 | O15: =N15/G15 -> 181.25 | P15: James Quintero
A16: 46084 | B16: 0.92708333 | C16: 0.23611111 | D16: =1+C16-B16 -> 0.30902778 | E16: =F15 -> 2342794 | F16: 2343602 | G16: =(F16-E16)/100 -> 8.08 | L16: 50 | M16: =71+28 -> 99 | N16: =+(($H$6*H16)+($J$6*J16)+($K$6*K16)+($L$6*L16)+($M$6*M16)+(I16*3)) -> 3225 | O16: =N16/G16 -> 399.13366 | P16: Michell Romero
A17: 46085 | B17: 0.27708333 | C17: 0.57361111 | D17: =1+C17-B17 -> 1.2965278 | E17: =F16 -> 2343602 | F17: 2344417 | G17: =(F17-E17)/100 -> 8.15 | M17: 119 | N17: =+(($H$6*H17)+($J$6*J17)+($K$6*K17)+($L$6*L17)+($M$6*M17)+(I17*3)) -> 2975 | O17: =N17/G17 -> 365.03067 | P17: Michell Romero
A18: 46085 | B18: 0.58333333 | C18: 0.74305556 | D18: =1+C18-B18 -> 1.1597222 | E18: =F17 -> 2344417 | F18: 2344836 | G18: =(F18-E18)/100 -> 4.19 | M18: 60 | N18: =+(($H$6*H18)+($J$6*J18)+($K$6*K18)+($L$6*L18)+($M$6*M18)+(I18*3)) -> 1500 | O18: =N18/G18 -> 357.99523 | P18: quejada diego
A19: 46085 | B19: 0.76319444 | C19: 0.90972222 | D19: =1+C19-B19 -> 1.1465278 | E19: =F18 -> 2344836 | F19: 2345202 | G19: =(F19-E19)/100 -> 3.66 | M19: 55 | N19: =+(($H$6*H19)+($J$6*J19)+($K$6*K19)+($L$6*L19)+($M$6*M19)+(I19*3)) -> 1375 | O19: =N19/G19 -> 375.68306 | P19: James Quintero
A20: 46085 | B20: 0.95486111 | C20: 0.24097222 | D20: =1+C20-B20 -> 0.28611111 | E20: =F19 -> 2345202 | F20: 2345938 | G20: =(F20-E20)/100 -> 7.36 | M20: =91+27 -> 118 | N20: =+(($H$6*H20)+($J$6*J20)+($K$6*K20)+($L$6*L20)+($M$6*M20)+(I20*3)) -> 2950 | O20: =N20/G20 -> 400.81522 | P20: Michell Romero
A21: 46086 | B21: 0.25902778 | C21: 0.57638889 | D21: =1+C21-B21 -> 1.3173611 | E21: =F20 -> 2345938 | F21: 2346222 | G21: =(F21-E21)/100 -> 2.84 | J21: 50 | M21: 96 | N21: =+(($H$6*H21)+($J$6*J21)+($K$6*K21)+($L$6*L21)+($M$6*M21)+(I21*3)) -> 3100 | O21: =N21/G21 -> 1091.5493 | P21: yeison
A22: 46086 | B22: 0.59375 | C22: 0.73611111 | D22: =1+C22-B22 -> 1.1423611 | E22: 2346714 | F22: 2347119 | G22: =(F22-E22)/100 -> 4.05 | M22: 59 | N22: =+(($H$6*H22)+($J$6*J22)+($K$6*K22)+($L$6*L22)+($M$6*M22)+(I22*3)) -> 1475 | O22: =N22/G22 -> 364.19753 | P22: quejada diego
A23: 46086 | B23: 0.75347222 | C23: 0.90138889 | D23: =1+C23-B23 -> 1.1479167 | E23: =F22 -> 2347119 | F23: 2347495 | G23: =(F23-E23)/100 -> 3.76 | I23: 200 | M23: 33 | N23: =+(($H$6*H23)+($J$6*J23)+($K$6*K23)+($L$6*L23)+($M$6*M23)+(I23*3)) -> 1425 | O23: =N23/G23 -> 378.98936 | P23: david
A24: 46086 | B24: 0.92708333 | C24: 0.24166667 | D24: =1+C24-B24 -> 0.31458333 | E24: =F23 -> 2347495 | F24: 2348320 | G24: =(F24-E24)/100 -> 8.25 | I24: 198 | M24: 104 | N24: =+(($H$6*H24)+($J$6*J24)+($K$6*K24)+($L$6*L24)+($M$6*M24)+(I24*3)) -> 3194 | O24: =N24/G24 -> 387.15152 | P24: Michell Romero
A25: 46087 | B25: 0.25902778 | C25: 0.56458333 | D25: =1+C25-B25 -> 1.3055556 | E25: =F24 -> 2348320 | F25: 2349123 | G25: =(F25-E25)/100 -> 8.03 | L25: 92 | M25: =28+35 -> 63 | N25: =+(($H$6*H25)+($J$6*J25)+($K$6*K25)+($L$6*L25)+($M$6*M25)+(I25*3)) -> 2955 | O25: =N25/G25 -> 367.99502 | P25: yeison
A26: 46087 | B26: 0.58611111 | C26: 0.74722222 | D26: =1+C26-B26 -> 1.1611111 | E26: =F25 -> 2349123 | F26: 2349530 | G26: =(F26-E26)/100 -> 4.07 | L26: 118 | N26: =+(($H$6*H26)+($J$6*J26)+($K$6*K26)+($L$6*L26)+($M$6*M26)+(I26*3)) -> 1770 | O26: =N26/G26 -> 434.88943 | P26: quejada diego
A27: 46087 | B27: 0.76597222 | C27: 0.90277778 | D27: =1+C27-B27 -> 1.1368056 | E27: =F26 -> 2349530 | F27: 2349895 | G27: 3 | J27: 50 | M27: 32 | N27: =+(($H$6*H27)+($J$6*J27)+($K$6*K27)+($L$6*L27)+($M$6*M27)+(I27*3)) -> 1500 | O27: =N27/G27 -> 500 | P27: quejada diego
A28: 46087 | B28: 0.94097222 | C28: 0.23263889 | D28: =1+C28-B28 -> 0.29166667 | E28: =F27 -> 2349895 | F28: 2350694 | G28: =(F28-E28)/100 -> 7.99 | L28: 95 | M28: 70 | N28: =+(($H$6*H28)+($J$6*J28)+($K$6*K28)+($L$6*L28)+($M$6*M28)+(I28*3)) -> 3175 | O28: =N28/G28 -> 397.37171 | P28: Michell Romero
A29: 46088 | B29: 0.25 | C29: 0.57430556 | D29: =1+C29-B29 -> 1.3243056 | E29: =F28 -> 2350694 | F29: 2351285 | G29: =(F29-E29)/100 -> 5.91 | K29: 20 | L29: 76 | M29: 30 | N29: =+(($H$6*H29)+($J$6*J29)+($K$6*K29)+($L$6*L29)+(13*M29)+(I29*3)) -> 1670 | O29: =N29/G29 -> 282.57191 | P29: quejada diego | Q29: se tiene apagada maquinaria 2 hoas y 38 minutos
A30: 46088 | B30: 0.59375 | C30: 0.73958333 | D30: =1+C30-B30 -> 1.1458333 | E30: =F29 -> 2351285 | F30: 2351684 | G30: =(F30-E30)/100 -> 3.99 | K30: 126 | M30: 20 | N30: =+(($H$6*H30)+($J$6*J30)+($K$6*K30)+($L$6*L30)+($M$6*M30)+(I30*3)) -> 1382 | O30: =N30/G30 -> 346.36591 | P30: yeison
A31: 46088 | B31: 0.75486111 | C31: 0.90277778 | D31: =1+C31-B31 -> 1.1479167 | E31: =F30 -> 2351684 | F31: 2352045 | G31: =(F31-E31)/100 -> 3.61 | M31: 67 | N31: =+(($H$6*H31)+($J$6*J31)+($K$6*K31)+($L$6*L31)+($M$6*M31)+(I31*3)) -> 1675 | O31: =N31/G31 -> 463.98892 | P31: david
A32: 46088 | B32: 0.92361111 | C32: 0.24375 | D32: =1+C32-B32 -> 0.32013889 | E32: =F31 -> 2352045 | F32: 2352875 | G32: =(F32-E32)/100 -> 8.3 | M32: 133 | N32: =+(($H$6*H32)+($J$6*J32)+($K$6*K32)+($L$6*L32)+($M$6*M32)+(I32*3)) -> 3325 | O32: =N32/G32 -> 400.60241 | P32: Michell Romero
A33: 46089 | B33: 0.26458333 | C33: 0.67361111 | D33: =1+C33-B33 -> 1.4090278 | E33: =F32 -> 2352875 | F33: 2353896 | G33: =(F33-E33)/100 -> 10.21 | J33: 50 | M33: 122 | N33: =+(($H$6*H33)+($J$6*J33)+($K$6*K33)+($L$6*L33)+($M$6*M33)+(I33*3)) -> 3750 | O33: =N33/G33 -> 367.28697 | P33: quejada diego
A34: 46089 | B34: 0.048611111 | C34: 0.23611111 | D34: =1+C34-B34 -> 1.1875 | E34: =F33 -> 2353896 | F34: 2354425 | G34: =(F34-E34)/100 -> 5.29 | M34: 83 | N34: =+(($H$6*H34)+($J$6*J34)+($K$6*K34)+($L$6*L34)+($M$6*M34)+(I34*3)) -> 2075 | O34: =N34/G34 -> 392.24953 | P34: david
A35: 46090 | B35: 0.25625 | C35: 0.57291667 | D35: =1+C35-B35 -> 1.3166667 | E35: =F34 -> 2354425 | F35: 2355193 | G35: =(F35-E35)/100 -> 7.68 | M35: 116 | N35: =+(($H$6*H35)+($J$6*J35)+($K$6*K35)+($L$6*L35)+($M$6*M35)+(I35*3)) -> 2900 | O35: =N35/G35 -> 377.60417 | P35: Andres Tinoco | Q35: se apaga maquinaria 30 min por lavado
A36: 46090 | B36: 0.58611111 | C36: 0.74583333 | D36: =1+C36-B36 -> 1.1597222 | E36: =F35 -> 2355193 | F36: 2355652 | G36: =(F36-E36)/100 -> 4.59 | M36: =39+11+13 -> 63 | N36: =+(($H$6*H36)+($J$6*J36)+($K$6*K36)+($L$6*L36)+($M$6*M36)+(I36*3)) -> 1575 | O36: =N36/G36 -> 343.13725 | P36: luis torres
A37: 46090 | B37: 0.76388889 | C37: 0.90625 | D37: =1+C37-B37 -> 1.1423611 | E37: =F36 -> 2355652 | F37: 2355996 | G37: =(F37-E37)/100 -> 3.44 | M37: 60 | N37: =+(($H$6*H37)+($J$6*J37)+($K$6*K37)+($L$6*L37)+($M$6*M37)+(I37*3)) -> 1500 | O37: =N37/G37 -> 436.04651 | P37: da
A38: 46090 | B38: 0.94444444 | C38: 0.23611111 | D38: =1+C38-B38 -> 0.29166667 | E38: =F37 -> 2355996 | F38: 2356783 | G38: =(F38-E38)/100 -> 7.87 | M38: 126 | N38: =+(($H$6*H38)+($J$6*J38)+($K$6*K38)+($L$6*L38)+($M$6*M38)+(I38*3)) -> 3150 | O38: =N38/G38 -> 400.25413 | P38: david
A39: 46091 | B39: 0.25555556 | C39: 0.57638889 | D39: =1+C39-B39 -> 1.3208333 | E39: =F38 -> 2356783 | F39: 2357612 | G39: =(F39-E39)/100 -> 8.29 | M39: =103+27 -> 130 | N39: =+(($H$6*H39)+($J$6*J39)+($K$6*K39)+($L$6*L39)+($M$6*M39)+(I39*3)) -> 3250 | O39: =N39/G39 -> 392.0386 | P39: Andres Tinoco
A40: 46091 | B40: 0.59861111 | C40: 0.74444444 | D40: =1+C40-B40 -> 1.1458333 | E40: =F39 -> 2357612 | F40: 2358010 | G40: =(F40-E40)/100 -> 3.98 | M40: 58 | N40: =+(($H$6*H40)+($J$6*J40)+($K$6*K40)+($L$6*L40)+($M$6*M40)+(I40*3)) -> 1450 | O40: =N40/G40 -> 364.32161 | P40: Andres Tinoco
...

Sheet MAQUINA DE ESCARCHA GRUESA
A1: COMPAÑÍA OPITA DE FRIO SAS | H1: ESCARCHA GRUESA
A2: CONTROL DE TIEMPO DE PRODUCCION
A3: LINEA DEL AGUA
B4: TIEMPO HORARICA | E4: CONTROL HOROMETRO | H4: PRODUCTOS | Q4: PLASTICO ENTREGADO | R4: USADO | S4: TOTAL PLASTIC | T4: ACUMULADO | U4: OBSERVACIONES
A5: FECHA | B5: HORA INIC | C5: HORA FIN | D5: TIEMP PRENDIDA | E5: HOROM INC | F5: HOROM FIN | G5: TIEMP PROD | H5: BTO ESCARCHA | I5: BTO FINOS | J5: ARROBA ESCARCHA | K5: 15 KG DE ESCARCHA | L5: KIL/PROD BTO | M5: KIL/PROD FINOS | N5: KIL/PROD ARROBAS | O5: ACUM KILOS | P5: PROD POR HORA | Q5: BOLSAS | R5: BOLSAS | S5: DIARIO | T5: PLASTICO | U5: AYUDANTE | V5: OBSERVACION
H6: 25 | I6: 26 | J6: 13 | K6: 15
A7: 46082 | B7: 0.25555556 | C7: 0.74027778 | D7: =1+C7-B7 -> 1.4847222 | E7: 519895 | F7: 521017 | G7: =(F7-E7)/100 -> 11.22 | H7: 246 | L7: =+H7*$H$6 -> 6150 | M7: =+$I$6*I7 -> 0 | N7: =+J7*$J$6+(K7*15) -> 0 | O7: =+L7+M7+N7 -> 6150 | P7: =(O7/G7) -> 548.12834 | Q7: 279 | R7: =H7+I7 -> 246 | S7: =R7-Q7 -> -33 | T7: =S7 -> -33 | U7: Daniel Garcia
A8: 46082 | B8: 0.76041667 | C8: 0.24166667 | D8: =1+C8-B8 -> 0.48125 | E8: =F7 -> 521017 | F8: 522227 | G8: =(F8-E8)/100 -> 12.1 | H8: 252 | L8: =+H8*$H$6 -> 6300 | M8: =+$I$6*I8 -> 0 | N8: =+J8*$J$6+(K8*15) -> 0 | O8: =+L8+M8+N8 -> 6300 | P8: =(O8/G8) -> 520.66116 | Q8: 275 | R8: =H8+I8 -> 252 | S8: =R8-Q8 -> -23 | T8: =-S7-(S8) -> 56 | U8: Jhoan Sebastian
A9: 46083 | B9: 0.25694444 | C9: 0.57569444 | D9: =1+C9-B9 -> 1.31875 | E9: =F8 -> 522227 | F9: 523028 | G9: 8 | H9: 176 | L9: =+H9*$H$6 -> 4400 | M9: =+$I$6*I9 -> 0 | N9: =+J9*$J$6+(K9*15) -> 0 | O9: =+L9+M9+N9 -> 4400 | P9: =(O9/G9) -> 550 | Q9: 200 | R9: =H9+I9 -> 176 | S9: =R9-Q9 -> -24 | T9: =-S8-(S9) -> 47 | U9: Oscar Andres
A10: 46083 | B10: 0.59027778 | C10: 0.74097222 | D10: =1+C10-B10 -> 1.1506944 | E10: =F9 -> 523028 | F10: 523424 | G10: 3 | H10: 49 | K10: 50 | L10: =+H10*$H$6 -> 1225 | M10: =+$I$6*I10 -> 0 | N10: =+J10*$J$6+(K10*15) -> 750 | O10: =+L10+M10+N10 -> 1975 | P10: =(O10/G10) -> 658.33333 | Q10: 100 | R10: =H10+I10 -> 49 | S10: =R10-Q10 -> -51 | T10: =T9-(S10) -> 98 | U10: Daniel Garcia
A11: 46083 | B11: 0.77569444 | C11: 0.90694444 | D11: =1+C11-B11 -> 1.13125 | E11: =F10 -> 523424 | F11: 523774 | G11: =(F11-E11)/100 -> 3.5 | H11: 91 | L11: =+H11*$H$6 -> 2275 | M11: =+$I$6*I11 -> 0 | N11: =+J11*$J$6+(K11*15) -> 0 | O11: =+L11+M11+N11 -> 2275 | P11: =(O11/G11) -> 650 | Q11: 100 | R11: =H11+I11 -> 91 | S11: =R11-Q11 -> -9 | T11: =T10-(S11) -> 107 | U11: Humberto
A12: 46083 | B12: 0.92361111 | C12: 0.24722222 | D12: =1+C12-B12 -> 0.32361111 | E12: =F11 -> 523774 | F12: 524603 | G12: =(F12-E12)/100 -> 8.29 | H12: 187 | L12: =+H12*$H$6 -> 4675 | M12: =+$I$6*I12 -> 0 | N12: =+J12*$J$6+(K12*15) -> 0 | O12: =+L12+M12+N12 -> 4675 | P12: =(O12/G12) -> 563.93245 | Q12: 100 | R12: =H12+I12 -> 187 | S12: =R12-Q12 -> 87 | T12: =T11-(S12) -> 20 | U12: Diego Uribe
A13: 46084 | B13: 0.25972222 | C13: 0.57152778 | D13: =1+C13-B13 -> 1.3118056 | E13: =F12 -> 524603 | F13: 525332 | G13: =(F13-E13)/100 -> 7.29 | H13: 153 | L13: =+H13*$H$6 -> 3825 | M13: =+$I$6*I13 -> 0 | N13: =+J13*$J$6+(K13*15) -> 0 | O13: =+L13+M13+N13 -> 3825 | P13: =(O13/G13) -> 524.69136 | Q13: 150 | R13: =H13+I13 -> 153 | S13: =R13-Q13 -> 3 | T13: =T12-(S13) -> 17 | U13: Oscar Andres
A14: 46084 | B14: 0.58680556 | C14: 0.78472222 | D14: =1+C14-B14 -> 1.1979167 | E14: =F13 -> 525332 | F14: 525748 | G14: =(F14-E14)/100 -> 4.16 | H14: 92 | L14: =+H14*$H$6 -> 2300 | M14: =+$I$6*I14 -> 0 | N14: =+J14*$J$6+(K14*15) -> 0 | O14: =+L14+M14+N14 -> 2300 | P14: =(O14/G14) -> 552.88462 | Q14: 100 | R14: =H14+I14 -> 92 | S14: =R14-Q14 -> -8 | T14: =T13-(S14) -> 25 | U14: quejada diego
A15: 46084 | B15: 0.77083333 | C15: 0.91180556 | D15: =1+C15-B15 -> 1.1409722 | E15: =F14 -> 525748 | F15: 526111 | G15: =(F15-E15)/100 -> 3.63 | H15: 81 | L15: =+H15*$H$6 -> 2025 | M15: =+$I$6*I15 -> 0 | N15: =+J15*$J$6+(K15*15) -> 0 | O15: =+L15+M15+N15 -> 2025 | P15: =(O15/G15) -> 557.85124 | Q15: 100 | R15: =H15+I15 -> 81 | S15: =R15-Q15 -> -19 | T15: =T14-(S15) -> 44 | U15: quejada diego
A16: 46084 | B16: 0.92361111 | C16: 0.23472222 | D16: =1+C16-B16 -> 0.31111111 | E16: =F15 -> 526111 | F16: 526922 | G16: =(F16-E16)/100 -> 8.11 | H16: 174 | L16: =+H16*$H$6 -> 4350 | M16: =+$I$6*I16 -> 0 | N16: =+J16*$J$6+(K16*15) -> 0 | O16: =+L16+M16+N16 -> 4350 | P16: =(O16/G16) -> 536.37485 | Q16: 200 | R16: =H16+I16 -> 174 | S16: =R16-Q16 -> -26 | T16: =T15-(S16) -> 70 | U16: Yinso Novoa
A17: 46085 | B17: 0.25277778 | C17: 0.58263889 | D17: =1+C17-B17 -> 1.3298611 | E17: =F16 -> 526922 | F17: 527729 | G17: =(F17-E17)/100 -> 8.07 | H17: 173 | L17: =+H17*$H$6 -> 4325 | M17: =+$I$6*I17 -> 0 | N17: =+J17*$J$6+(K17*15) -> 0 | O17: =+L17+M17+N17 -> 4325 | P17: =(O17/G17) -> 535.93556 | Q17: 200 | R17: =H17+I17 -> 173 | S17: =R17-Q17 -> -27 | T17: =T16-(S17) -> 97 | U17: Oscar Andres
A18: 46085 | B18: 0.6 | C18: 0.74305556 | D18: =1+C18-B18 -> 1.1430556 | E18: =F17 -> 527729 | F18: 528109 | G18: 4 | H18: 84 | L18: =+H18*$H$6 -> 2100 | M18: =+$I$6*I18 -> 0 | N18: =+J18*$J$6+(K18*15) -> 0 | O18: =+L18+M18+N18 -> 2100 | P18: =(O18/G18) -> 525 | Q18: 100 | R18: =H18+I18 -> 84 | S18: =R18-Q18 -> -16 | T18: =T17-(S18) -> 113 | U18: ja
A19: 46085 | B19: 0.76805556 | C19: 0.90694444 | D19: =1+C19-B19 -> 1.1388889 | E19: =F18 -> 528109 | F19: 528508 | G19: =(F19-E19)/100 -> 3.99 | H19: 83 | L19: =+H19*$H$6 -> 2075 | M19: =+$I$6*I19 -> 0 | N19: =+J19*$J$6+(K19*15) -> 0 | O19: =+L19+M19+N19 -> 2075 | P19: =(O19/G19) -> 520.05013 | Q19: 50 | R19: =H19+I19 -> 83 | S19: =R19-Q19 -> 33 | T19: =T18-(S19) -> 80 | U19: hernandez luis
A20: 46085 | B20: 0.94861111 | C20: 0.23958333 | D20: =1+C20-B20 -> 0.29097222 | E20: =F19 -> 528508 | F20: 529267 | G20: =(F20-E20)/100 -> 7.59 | H20: 163 | L20: =+H20*$H$6 -> 4075 | M20: =+$I$6*I20 -> 0 | N20: =+J20*$J$6+(K20*15) -> 0 | O20: =+L20+M20+N20 -> 4075 | P20: =(O20/G20) -> 536.89065 | Q20: 100 | R20: =H20+I20 -> 163 | S20: =R20-Q20 -> 63 | T20: =T19-(S20) -> 17 | U20: Yinso Novoa | V20: se recibio maquina apagada y se prende a las 10:26
A21: 46086 | B21: 0.26944444 | C21: 0.57083333 | D21: =1+C21-B21 -> 1.3013889 | E21: =F20 -> 529267 | F21: 530062 | G21: =(F21-E21)/100 -> 7.95 | H21: 160 | L21: =+H21*$H$6 -> 4000 | M21: =+$I$6*I21 -> 0 | N21: =+J21*$J$6+(K21*15) -> 0 | O21: =+L21+M21+N21 -> 4000 | P21: =(O21/G21) -> 503.14465 | Q21: 150 | R21: =H21+I21 -> 160 | S21: =R21-Q21 -> 10 | T21: =T20-(S21) -> 7 | U21: Oscar Andres
A22: 46086 | B22: 0.5875 | C22: 0.74097222 | D22: =1+C22-B22 -> 1.1534722 | E22: =F21 -> 530062 | F22: 530443 | G22: =(F22-E22)/100 -> 3.81 | H22: 69 | K22: 35 | L22: =+H22*$H$6 -> 1725 | M22: =+$I$6*I22 -> 0 | N22: =+J22*$J$6+(K22*15) -> 525 | O22: =+L22+M22+N22 -> 2250 | P22: =(O22/G22) -> 590.55118 | Q22: 100 | R22: =H22+I22 -> 69 | S22: =R22-Q22 -> -31 | T22: =T21-(S22) -> 38 | U22: DAVID
A23: 46086 | B23: 0.75625 | C23: 0.90694444 | D23: =1+C23-B23 -> 1.1506944 | E23: =F22 -> 530443 | F23: 530855 | G23: =(F23-E23)/100 -> 4.12 | H23: 81 | L23: =+H23*$H$6 -> 2025 | M23: =+$I$6*I23 -> 0 | N23: =+J23*$J$6+(K23*15) -> 0 | O23: =+L23+M23+N23 -> 2025 | P23: =(O23/G23) -> 491.50485 | Q23: 100 | R23: =H23+I23 -> 81 | S23: =R23-Q23 -> -19 | T23: =T22-(S23) -> 57 | U23: hernandez luis
A24: 46086 | B24: 0.92222222 | C24: 0.24027778 | D24: =1+C24-B24 -> 0.31805556 | E24: =F23 -> 530855 | F24: 531649 | G24: =(F24-E24)/100 -> 7.94 | H24: 182 | L24: =+H24*$H$6 -> 4550 | M24: =+$I$6*I24 -> 0 | N24: =+J24*$J$6+(K24*15) -> 0 | O24: =+L24+M24+N24 -> 4550 | P24: =(O24/G24) -> 573.04786 | Q24: 200 | R24: =H24+I24 -> 182 | S24: =R24-Q24 -> -18 | T24: =T23-(S24) -> 75 | U24: Yinso Novoa
A25: 46087 | B25: 0.25486111 | C25: 0.575 | D25: =1+C25-B25 -> 1.3201389 | E25: =F24 -> 531649 | F25: 532454 | G25: =(F25-E25)/100 -> 8.05 | H25: 170 | L25: =+H25*$H$6 -> 4250 | M25: =+$I$6*I25 -> 0 | N25: =+J25*$J$6+(K25*15) -> 0 | O25: =+L25+M25+N25 -> 4250 | P25: =(O25/G25) -> 527.95031 | Q25: 200 | R25: =H25+I25 -> 170 | S25: =R25-Q25 -> -30 | T25: =T24-(S25) -> 105 | U25: Oscar Andres
A26: 46087 | B26: 0.59236111 | C26: 0.74930556 | D26: =1+C26-B26 -> 1.1569444 | E26: =F25 -> 532454 | F26: 532864 | G26: =(F26-E26)/100 -> 4.1 | H26: 89 | L26: =+H26*$H$6 -> 2225 | M26: =+$I$6*I26 -> 0 | N26: =+J26*$J$6+(K26*15) -> 0 | O26: =+L26+M26+N26 -> 2225 | P26: =(O26/G26) -> 542.68293 | Q26: 100 | R26: =H26+I26 -> 89 | S26: =R26-Q26 -> -11 | T26: =T25-(S26) -> 116 | U26: DAVID
A27: 46087 | B27: 0.76527778 | C27: 0.90972222 | D27: =1+C27-B27 -> 1.1444444 | E27: =F26 -> 532864 | F27: 533246 | G27: =(F27-E27)/100 -> 3.82 | H27: 83 | L27: =+H27*$H$6 -> 2075 | M27: =+$I$6*I27 -> 0 | N27: =+J27*$J$6+(K27*15) -> 0 | O27: =+L27+M27+N27 -> 2075 | P27: =(O27/G27) -> 543.19372 | Q27: 100 | R27: =H27+I27 -> 83 | S27: =R27-Q27 -> -17 | T27: =T26-(S27) -> 133 | U27: quejada diego
A28: 46087 | B28: 0.92708333 | C28: 0.24305556 | D28: =1+C28-B28 -> 0.31597222 | E28: =F27 -> 533246 | F28: 534066 | G28: =(F28-E28)/100 -> 8.2 | H28: =132+28 -> 160 | L28: =+H28*$H$6 -> 4000 | M28: =+$I$6*I28 -> 0 | N28: =+J28*$J$6+(K28*15) -> 0 | O28: =+L28+M28+N28 -> 4000 | P28: =(O28/G28) -> 487.80488 | Q28: 100 | R28: =H28+I28 -> 160 | S28: =R28-Q28 -> 60 | T28: =T27-(S28) -> 73 | U28: Yinso Novoa
A29: 46088 | B29: 0.26736111 | C29: 0.57916667 | D29: =1+C29-B29 -> 1.3118056 | E29: =F28 -> 534066 | F29: 534869 | G29: 8 | H29: 171 | L29: =+H29*$H$6 -> 4275 | M29: =+$I$6*I29 -> 0 | N29: =+J29*$J$6+(K29*15) -> 0 | O29: =+L29+M29+N29 -> 4275 | P29: =(O29/G29) -> 534.375 | Q29: 200 | R29: =H29+I29 -> 171 | S29: =R29-Q29 -> -29 | T29: =T28-(S29) -> 102 | U29: Oscar Andres
A30: 46088 | B30: 0.59444444 | C30: 0.74930556 | D30: =1+C30-B30 -> 1.1548611 | E30: =F29 -> 534869 | F30: 535268 | G30: 8 | H30: 87 | L30: =+H30*$H$6 -> 2175 | M30: =+$I$6*I30 -> 0 | N30: =+J30*$J$6+(K30*15) -> 0 | O30: =+L30+M30+N30 -> 2175 | P30: =(O30/G30) -> 271.875 | Q30: 100 | R30: =H30+I30 -> 87 | S30: =R30-Q30 -> -13 | T30: =T29-(S30) -> 115 | U30: Andres Tinoco
A31: 46088 | B31: 0.76319444 | C31: 0.90763889 | D31: =1+C31-B31 -> 1.1444444 | E31: =F30 -> 535268 | F31: 535662 | G31: =(F31-E31)/100 -> 3.94 | H31: 80 | L31: =+H31*$H$6 -> 2000 | M31: =+$I$6*I31 -> 0 | N31: =+J31*$J$6+(K31*15) -> 0 | O31: =+L31+M31+N31 -> 2000 | P31: =(O31/G31) -> 507.61421 | Q31: 100 | R31: =H31+I31 -> 80 | S31: =R31-Q31 -> -20 | T31: =T30-(S31) -> 135 | U31: Andres Tinoco
A32: 46088 | B32: 0.92361111 | C32: 0.24305556 | D32: =1+C32-B32 -> 0.31944444 | E32: =F31 -> 535662 | F32: 536448 | G32: =(F32-E32)/100 -> 7.86 | H32: 171 | L32: =+H32*$H$6 -> 4275 | M32: =+$I$6*I32 -> 0 | N32: =+J32*$J$6+(K32*15) -> 0 | O32: =+L32+M32+N32 -> 4275 | P32: =(O32/G32) -> 543.89313 | Q32: 200 | R32: =H32+I32 -> 171 | S32: =R32-Q32 -> -29 | T32: =T31-(S32) -> 164 | U32: Yinso Novoa
A33: 46089 | B33: 0.25416667 | C33: 0.65902778 | D33: =1+C33-B33 -> 1.4048611 | E33: 472837 | F33: 537423 | G33: 8 | H33: 200 | L33: =+H33*$H$6 -> 5000 | M33: =+$I$6*I33 -> 0 | N33: =+J33*$J$6+(K33*15) -> 0 | O33: =+L33+M33+N33 -> 5000 | P33: =(O33/G33) -> 625 | Q33: 200 | R33: =H33+I33 -> 200 | S33: =R33-Q33 -> 0 | T33: =T32-(S33) -> 164 | U33: luis torres
A34: 46089 | B34: 0.54722222 | C34: 0.74097222 | D34: =1+C34-B34 -> 1.19375 | E34: =F33 -> 537423 | F34: 538029 | G34: 3 | H34: 103 | L34: =+H34*$H$6 -> 2575 | M34: =+$I$6*I34 -> 0 | N34: =+J34*$J$6+(K34*15) -> 0 | O34: =+L34+M34+N34 -> 2575 | P34: =(O34/G34) -> 858.33333 | Q34: 150 | R34: =H34+I34 -> 103 | S34: =R34-Q34 -> -47 | T34: =T33-(S34) -> 211 | U34: hernandez luis
A35: 46090 | B35: 0.25347222 | C35: 0.57638889 | D35: =1+C35-B35 -> 1.3229167 | E35: 538043 | F35: 538804 | G35: 8 | H35: 184 | L35: =+H35*$H$6 -> 4600 | M35: =+$I$6*I35 -> 0 | N35: =+J35*$J$6+(K35*15) -> 0 | O35: =+L35+M35+N35 -> 4600 | P35: =(O35/G35) -> 575 | Q35: 200 | R35: =H35+I35 -> 184 | S35: =R35-Q35 -> -16 | T35: =T34-(S35) -> 227 | U35: Yeisson
